Workbook

Sheet Registro_Actividades
A1: Fecha | B1: Semana | C1: Nombre Trabajador | D1: DPI | E1: Actividad | F1: Lote | G1: Unidad | H1: Cantidad | I1: Precio Unitario | J1: Total Devengado
A2: 46111 | B2: =WEEKNUM(A2,2) -> 14 | C2: HENRY RANDOLFO HERNANDEZ | E2: encargado de beneficio | F2: Beneficio | G2: =IFERROR(VLOOKUP(E2,Control_Actividades!A:C,2,FALSE),) -> Dia | H2: 1 | I2: =IFERROR(VLOOKUP(E2,Control_Actividades!A:C,3,FALSE),"") -> 130 | J2: =H2*I2 -> 130
A3: 46111 | B3: =WEEKNUM(A3,2) -> 14 | C3: CARMELO GUAMUCH | E3: Corte de Café | F3: corona | G3: =IFERROR(VLOOKUP(E3,Control_Actividades!A:C,2,FALSE),) -> Quintal | H3: 0.8 | I3: =IFERROR(VLOOKUP(E3,Control_Actividades!A:C,3,FALSE),"") -> 70 | J3: =H3*I3 -> 56
A4: 46111 | B4: =WEEKNUM(A4,2) -> 14 | C4: LUZ DE MARIA MARTINEZ | E4: Corte de Café | F4: corona | G4: =IFERROR(VLOOKUP(E4,Control_Actividades!A:C,2,FALSE),) -> Quintal | H4: 0.85 | I4: =IFERROR(VLOOKUP(E4,Control_Actividades!A:C,3,FALSE),"") -> 70 | J4: =H4*I4 -> 59.5
A5: 46111 | B5: =WEEKNUM(A5,2) -> 14 | C5: JAIME ANIBAL MARROQUIN | E5: Corte de Café | F5: corona | G5: =IFERROR(VLOOKUP(E5,Control_Actividades!A:C,2,FALSE),) -> Quintal | H5: 0.85 | I5: =IFERROR(VLOOKUP(E5,Control_Actividades!A:C,3,FALSE),"") -> 70 | J5: =H5*I5 -> 59.5
A6: 46111 | B6: =WEEKNUM(A6,2) -> 14 | C6: SUSANA SOLANO | E6: Corte de Café | F6: corona | G6: =IFERROR(VLOOKUP(E6,Control_Actividades!A:C,2,FALSE),) -> Quintal | H6: 0.9 | I6: =IFERROR(VLOOKUP(E6,Control_Actividades!A:C,3,FALSE),"") -> 70 | J6: =H6*I6 -> 63
A7: 46111 | B7: =WEEKNUM(A7,2) -> 14 | C7: ENMA PEREZ | E7: Corte de Café | F7: corona | G7: =IFERROR(VLOOKUP(E7,Control_Actividades!A:C,2,FALSE),) -> Quintal | H7: 1.05 | I7: =IFERROR(VLOOKUP(E7,Control_Actividades!A:C,3,FALSE),"") -> 70 | J7: =H7*I7 -> 73.5
A8: 46111 | B8: =WEEKNUM(A8,2) -> 14 | C8: EDGAR ROLANDO NAVAS | E8: Corte de Café | F8: corona | G8: =IFERROR(VLOOKUP(E8,Control_Actividades!A:C,2,FALSE),) -> Quintal | H8: 1.05 | I8: =IFERROR(VLOOKUP(E8,Control_Actividades!A:C,3,FALSE),"") -> 70 | J8: =H8*I8 -> 73.5
A9: 46111 | B9: =WEEKNUM(A9,2) -> 14 | C9: SULEIMA MARROQUIN | E9: Corte de Café | F9: corona | G9: =IFERROR(VLOOKUP(E9,Control_Actividades!A:C,2,FALSE),) -> Quintal | H9: 0.35 | I9: =IFERROR(VLOOKUP(E9,Control_Actividades!A:C,3,FALSE),"") -> 70 | J9: =H9*I9 -> 24.5
A10: 46111 | B10: =WEEKNUM(A10,2) -> 14 | C10: FERNANDO GUAMUCH | E10: Corte de Café | F10: corona | G10: =IFERROR(VLOOKUP(E10,Control_Actividades!A:C,2,FALSE),) -> Quintal | H10: 0.4 | I10: =IFERROR(VLOOKUP(E10,Control_Actividades!A:C,3,FALSE),"") -> 70 | J10: =H10*I10 -> 28
A11: 46111 | B11: =WEEKNUM(A11,2) -> 14 | C11: GERMAN SOLANO | E11: Corte de Café | F11: corona | G11: =IFERROR(VLOOKUP(E11,Control_Actividades!A:C,2,FALSE),) -> Quintal | H11: 1.05 | I11: =IFERROR(VLOOKUP(E11,Control_Actividades!A:C,3,FALSE),"") -> 70 | J11: =H11*I11 -> 73.5
A12: 46111 | B12: =WEEKNUM(A12,2) -> 14 | C12: CARLOS GARCIA | E12: Corte de Café | F12: corona | G12: =IFERROR(VLOOKUP(E12,Control_Actividades!A:C,2,FALSE),) -> Quintal | H12: 0.5 | I12: =IFERROR(VLOOKUP(E12,Control_Actividades!A:C,3,FALSE),"") -> 70 | J12: =H12*I12 -> 35
A13: 46111 | B13: =WEEKNUM(A13,2) -> 14 | C13: JULIA MARROQUIN | E13: Corte de Café | F13: corona | G13: =IFERROR(VLOOKUP(E13,Control_Actividades!A:C,2,FALSE),) -> Quintal | H13: 0.5 | I13: =IFERROR(VLOOKUP(E13,Control_Actividades!A:C,3,FALSE),"") -> 70 | J13: =H13*I13 -> 35
... A16: 46111 | B16: =WEEKNUM(A16,2) -> 14 | C16: OLIVER AGUILAR | E16: Corte de Café | F16: corona | G16: =IFERROR(VLOOKUP(E16,Control_Actividades!A:C,2,FALSE),) -> Quintal | H16: 0.8 | I16: =IFERROR(VLOOKUP(E16,Control_Actividades!A:C,3,FALSE),"") -> 70 | J16: =H16*I16 -> 56
A17: 46111 | B17: =WEEKNUM(A17,2) -> 14 | C17: ELMER MANUEL HERNANDEZ | E17: Beneficio | F17: Beneficio | G17: dia | H17: 1 | I17: 100 | J17: =H17*I17 -> 100
A18: 46111 | B18: =WEEKNUM(A18,2) -> 14 | C18: JONATHAN AGUILAR | E18: Corte de Café | F18: corona | G18: =IFERROR(VLOOKUP(E18,Control_Actividades!A:C,2,FALSE),) -> Quintal | H18: 0.4 | I18: =IFERROR(VLOOKUP(E18,Control_Actividades!A:C,3,FALSE),"") -> 70 | J18: =H18*I18 -> 28
A19: 46111 | B19: =WEEKNUM(A19,2) -> 14 | C19: AXEL ALVAREZ | E19: Poda | F19: corona | G19: =IFERROR(VLOOKUP(E19,Control_Actividades!A:C,2,FALSE),) -> Manzana | H19: 0.5 | I19: =IFERROR(VLOOKUP(E19,Control_Actividades!A:C,3,FALSE),"") -> 110 | J19: =H19*I19 -> 55
A20: 46111 | B20: =WEEKNUM(A20,2) -> 14 | C20: MARLENI SALAZAR | E20: Corte de Café | F20: corona | G20: =IFERROR(VLOOKUP(E20,Control_Actividades!A:C,2,FALSE),) -> Quintal | H20: 0.4 | I20: =IFERROR(VLOOKUP(E20,Control_Actividades!A:C,3,FALSE),"") -> 70 | J20: =H20*I20 -> 28
A21: 46111 | B21: =WEEKNUM(A21,2) -> 14 | C21: JORGE ODILIO SOLANO | E21: Corte de Café | F21: corona | G21: =IFERROR(VLOOKUP(E21,Control_Actividades!A:C,2,FALSE),) -> Quintal | H21: 1.15 | I21: =IFERROR(VLOOKUP(E21,Control_Actividades!A:C,3,FALSE),"") -> 70 | J21: =H21*I21 -> 80.5
A22: 46111 | B22: =WEEKNUM(A22,2) -> 14 | C22: DANILO SOLANO | E22: Corte de Café | F22: corona | G22: =IFERROR(VLOOKUP(E22,Control_Actividades!A:C,2,FALSE),) -> Quintal | H22: 0.55 | I22: =IFERROR(VLOOKUP(E22,Control_Actividades!A:C,3,FALSE),"") -> 70 | J22: =H22*I22 -> 38.5
A23: 46111 | B23: =WEEKNUM(A23,2) -> 14 | C23: JORGE MARROQUIN | E23: Corte de Café | F23: corona | G23: =IFERROR(VLOOKUP(E23,Control_Actividades!A:C,2,FALSE),) -> Quintal | I23: =IFERROR(VLOOKUP(E23,Control_Actividades!A:C,3,FALSE),"") -> 70 | J23: =H23*I23 -> 0
A24: 46111 | B24: =WEEKNUM(A24,2) -> 14 | C24: FRANCISCO NAVAS | E24: Corte de Café | F24: corona | G24: =IFERROR(VLOOKUP(E24,Control_Actividades!A:C,2,FALSE),) -> Quintal | H24: 0.45 | I24: =IFERROR(VLOOKUP(E24,Control_Actividades!A:C,3,FALSE),"") -> 70 | J24: =H24*I24 -> 31.5
A25: 46111 | B25: =WEEKNUM(A25,2) -> 14 | C25: ALEXANDER NAVAS | E25: Corte de Café | F25: corona | G25: =IFERROR(VLOOKUP(E25,Control_Actividades!A:C,2,FALSE),) -> Quintal | H25: 0.7 | I25: =IFERROR(VLOOKUP(E25,Control_Actividades!A:C,3,FALSE),"") -> 70 | J25: =H25*I25 -> 49
A26: 46111 | B26: =WEEKNUM(A26,2) -> 14 | C26: DIXON HERNANDEZ | E26: Corte de Café | F26: corona | G26: =IFERROR(VLOOKUP(E26,Control_Actividades!A:C,2,FALSE),) -> Quintal | H26: 0.7 | I26: =IFERROR(VLOOKUP(E26,Control_Actividades!A:C,3,FALSE),"") -> 70 | J26: =H26*I26 -> 49
A27: 46111 | B27: =WEEKNUM(A27,2) -> 14 | C27: FLORIDALMA ALVAREZ | E27: Corte de Café | F27: corona | G27: =IFERROR(VLOOKUP(E27,Control_Actividades!A:C,2,FALSE),) -> Quintal | H27: 1 | I27: =IFERROR(VLOOKUP(E27,Control_Actividades!A:C,3,FALSE),"") -> 70 | J27: =H27*I27 -> 70
A28: 46111 | B28: =WEEKNUM(A28,2) -> 14 | C28: WILFRIDO HERNANDEZ | E28: Corte de Café | F28: corona | G28: =IFERROR(VLOOKUP(E28,Control_Actividades!A:C,2,FALSE),) -> Quintal | H28: 1.2 | I28: =IFERROR(VLOOKUP(E28,Control_Actividades!A:C,3,FALSE),"") -> 70 | J28: =H28*I28 -> 84
A29: 46111 | B29: =WEEKNUM(A29,2) -> 14 | C29: TELMA HERNANDEZ | E29: Corte de Café | F29: corona | G29: =IFERROR(VLOOKUP(E29,Control_Actividades!A:C,2,FALSE),) -> Quintal | H29: 0.6 | I29: =IFERROR(VLOOKUP(E29,Control_Actividades!A:C,3,FALSE),"") -> 70 | J29: =H29*I29 -> 42
A30: 46111 | B30: =WEEKNUM(A30,2) -> 14 | C30: GABY ALVAREZ | E30: Corte de Café | F30: corona | G30: =IFERROR(VLOOKUP(E30,Control_Actividades!A:C,2,FALSE),) -> Quintal | H30: 0.6 | I30: =IFERROR(VLOOKUP(E30,Control_Actividades!A:C,3,FALSE),"") -> 70 | J30: =H30*I30 -> 42
A31: 46111 | B31: =WEEKNUM(A31,2) -> 14 | C31: NOHEMI ALVAREZ | E31: Corte de Café | F31: corona | G31: =IFERROR(VLOOKUP(E31,Control_Actividades!A:C,2,FALSE),) -> Quintal | H31: 0.75 | I31: =IFERROR(VLOOKUP(E31,Control_Actividades!A:C,3,FALSE),"") -> 70 | J31: =H31*I31 -> 52.5
A32: 46112 | B32: =WEEKNUM(A32,2) -> 14 | C32: HENRY RANDOLFO HERNANDEZ | E32: Encargado de beneficio | F32: Beneficio | G32: =IFERROR(VLOOKUP(E32,Control_Actividades!A:C,2,FALSE),) -> Dia | H32: 1 | I32: =IFERROR(VLOOKUP(E32,Control_Actividades!A:C,3,FALSE),"") -> 130 | J32: =H32*I32 -> 130
A33: 46112 | B33: =WEEKNUM(A33,2) -> 14 | C33: CARMELO GUAMUCH | E33: Corte de Café | F33: cañada | G33: =IFERROR(VLOOKUP(E33,Control_Actividades!A:C,2,FALSE),) -> Quintal | H33: 0.9 | I33: =IFERROR(VLOOKUP(E33,Control_Actividades!A:C,3,FALSE),"") -> 70 | J33: =H33*I33 -> 63
A34: 46112 | B34: =WEEKNUM(A34,2) -> 14 | C34: LUZ DE MARIA MARTINEZ | E34: Corte de Café | F34: cañada | G34: =IFERROR(VLOOKUP(E34,Control_Actividades!A:C,2,FALSE),) -> Quintal | H34: 0.95 | I34: =IFERROR(VLOOKUP(E34,Control_Actividades!A:C,3,FALSE),"") -> 70 | J34: =H34*I34 -> 66.5
A35: 46112 | B35: =WEEKNUM(A35,2) -> 14 | C35: JAIME ANIBAL MARROQUIN | E35: Corte de Café | F35: cañada | G35: =IFERROR(VLOOKUP(E35,Control_Actividades!A:C,2,FALSE),) -> Quintal | H35: 1.15 | I35: =IFERROR(VLOOKUP(E35,Control_Actividades!A:C,3,FALSE),"") -> 70 | J35: =H35*I35 -> 80.5
... A60: 46112 | B60: =WEEKNUM(A60,2) -> 14 | C60: GABY ALVAREZ | E60: Corte de Café | F60: cañada | G60: =IFERROR(VLOOKUP(E60,Control_Actividades!A:C,2,FALSE),) -> Quintal | H60: 0.65 | I60: =IFERROR(VLOOKUP(E60,Control_Actividades!A:C,3,FALSE),"") -> 70 | J60: =H60*I60 -> 45.5
A61: 46112 | B61: =WEEKNUM(A61,2) -> 14 | C61: NOHEMI ALVAREZ | E61: Corte de Café | F61: cañada | G61: =IFERROR(VLOOKUP(E61,Control_Actividades!A:C,2,FALSE),) -> Quintal | I61: =IFERROR(VLOOKUP(E61,Control_Actividades!A:C,3,FALSE),"") -> 70 | J61: =H61*I61 -> 0
A62: 46113 | B62: =WEEKNUM(A62,2) -> 14 | C62: HENRY RANDOLFO HERNANDEZ | E62: Encargado de beneficio | G62: =IFERROR(VLOOKUP(E62,Control_Actividades!A:C,2,FALSE),) -> Dia | H62: 1 | I62: =IFERROR(VLOOKUP(E62,Control_Actividades!A:C,3,FALSE),"") -> 130 | J62: =H62*I62 -> 130
A63: 46113 | B63: =WEEKNUM(A63,2) -> 14 | C63: CARMELO GUAMUCH | E63: Corte de Café | G63: =IFERROR(VLOOKUP(E63,Control_Actividades!A:C,2,FALSE),) -> Quintal | H63: 0.45 | I63: =IFERROR(VLOOKUP(E63,Control_Actividades!A:C,3,FALSE),"") -> 70 | J63: =H63*I63 -> 31.5
A64: 46113 | B64: =WEEKNUM(A64,2) -> 14 | C64: LUZ DE MARIA MARTINEZ | E64: Corte de Café | G64: =IFERROR(VLOOKUP(E64,Control_Actividades!A:C,2,FALSE),) -> Quintal | H64: 0.45 | I64: =IFERROR(VLOOKUP(E64,Control_Actividades!A:C,3,FALSE),"") -> 70 | J64: =H64*I64 -> 31.5
A65: 46113 | B65: =WEEKNUM(A65,2) -> 14 | C65: JAIME ANIBAL MARROQUIN | E65: Corte de Café | G65: =IFERROR(VLOOKUP(E65,Control_Actividades!A:C,2,FALSE),) -> Quintal | H65: 0.45 | I65: =IFERROR(VLOOKUP(E65,Control_Actividades!A:C,3,FALSE),"") -> 70 | J65: =H65*I65 -> 31.5
A66: 46113 | B66: =WEEKNUM(A66,2) -> 14 | C66: SUSANA SOLANO | E66: Corte de Café | G66: =IFERROR(VLOOKUP(E66,Control_Actividades!A:C,2,FALSE),) -> Quintal | H66: 0.35 | I66: =IFERROR(VLOOKUP(E66,Control_Actividades!A:C,3,FALSE),"") -> 70 | J66: =H66*I66 -> 24.5
...

Sheet Control_Actividades
A1: Actividad | B1: Unidad | C1: Precio Unitario
A2: Corte de Café | B2: Quintal | C2: 70
A3: Pepena | B3: Quintal | C3: 35
A4: Fertilización | B4: Hectárea | C4: 150
A5: Limpia Manual | B5: Jornal | C5: 50
A6: Poda | B6: Manzana | C6: 110
A7: Encargado de Beneficio | B7: Dia | C7: 130
A8: Beneficio | B8: Dia | C8: 100
A9: Mantenimiento general | B9: Dia | C9: 75
A10: Deshije | B10: Manzana | C10: 75

Sheet Resumen_Semanal
A1: Semana | B1: Nombre Trabajador | C1: Total Devengado | D1: Bonificación | E1: Anticipos | F1: Total a Pagar
A2: 14 | B2: HENRY RANDOLFO HERNANDEZ | C2: =SUMIFS(Registro_Actividades!J:J,Registro_Actividades!C:C,B2,Registro_Actividades!B:B,A2) -> 390 | F2: =C2+D2-E2 -> 390
A3: 14 | B3: CARMELO GUAMUCH | C3: =SUMIFS(Registro_Actividades!J:J,Registro_Actividades!C:C,B3,Registro_Actividades!B:B,A3) -> 150.5 | F3: =C3+D3-E3 -> 150.5
A4: 14 | B4: LUZ DE MARIA MARTINEZ | C4: =SUMIFS(Registro_Actividades!J:J,Registro_Actividades!C:C,B4,Registro_Actividades!B:B,A4) -> 157.5 | F4: =C4+D4-E4 -> 157.5
A5: 14 | B5: JAIME ANIBAL MARROQUIN | C5: =SUMIFS(Registro_Actividades!J:J,Registro_Actividades!C:C,B5,Registro_Actividades!B:B,A5) -> 171.5 | F5: =C5+D5-E5 -> 171.5
A6: 14 | B6: SUSANA SOLANO | C6: =SUMIFS(Registro_Actividades!J:J,Registro_Actividades!C:C,B6,Registro_Actividades!B:B,A6) -> 143.5 | F6: =C6+D6-E6 -> 143.5
A7: 14 | B7: ENMA PEREZ | C7: =SUMIFS(Registro_Actividades!J:J,Registro_Actividades!C:C,B7,Registro_Actividades!B:B,A7) -> 164.5 | F7: =C7+D7-E7 -> 164.5
A8: 14 | B8: EDGAR ROLANDO NAVAS | C8: =SUMIFS(Registro_Actividades!J:J,Registro_Actividades!C:C,B8,Registro_Actividades!B:B,A8) -> 234.5 | F8: =C8+D8-E8 -> 234.5
A9: 14 | B9: SULEIMA MARROQUIN | C9: =SUMIFS(Registro_Actividades!J:J,Registro_Actividades!C:C,B9,Registro_Actividades!B:B,A9) -> 91 | F9: =C9+D9-E9 -> 91
A10: 14 | B10: FERNANDO GUAMUCH | C10: =SUMIFS(Registro_Actividades!J:J,Registro_Actividades!C:C,B10,Registro_Actividades!B:B,A10) -> 168 | F10: =C10+D10-E10 -> 168
A11: 14 | B11: GERMAN SOLANO | C11: =SUMIFS(Registro_Actividades!J:J,Registro_Actividades!C:C,B11,Registro_Actividades!B:B,A11) -> 164.5 | F11: =C11+D11-E11 -> 164.5
A12: 14 | B12: CARLOS GARCIA | C12: =SUMIFS(Registro_Actividades!J:J,Registro_Actividades!C:C,B12,Registro_Actividades!B:B,A12) -> 98 | F12: =C12+D12-E12 -> 98
A13: 14 | B13: JULIA MARROQUIN | C13: =SUMIFS(Registro_Actividades!J:J,Registro_Actividades!C:C,B13,Registro_Actividades!B:B,A13) -> 98 | F13: =C13+D13-E13 -> 98
... A61: 15 | B61: NOHEMI ALVAREZ | C61: =SUMIFS(Registro_Actividades!J:J,Registro_Actividades!C:C,B61,Registro_Actividades!B:B,A61) -> 386 | F61: =C61+D61-E61 -> 386

Sheet RESUMEN PERSONAL
B1: PLANILLA DEL 30/3/2026 AL 11/4/2026
B2: Nombre Trabajador | C2: Total Devengado | D2: Bonificación | E2: Anticipos | F2: Total a Pagar | G2: DPI | H2: # DE CUENTA | I2: BANCO
B3: ADISTER ARCENIO | C3: =+SUMIFS(Resumen_Semanal!F:F,Resumen_Semanal!B:B,Resumen_Semanal!B15) -> 495 | D3: =+(4*75) -> 300 | F3: =C3+D3-E3 -> 795 | G3: 1698862470613 | H3: 4029152121 | I3: BANRURAL
B4: ALEXANDER NAVAS | C4: =+SUMIFS(Resumen_Semanal!F:F,Resumen_Semanal!B:B,Resumen_Semanal!B25) -> 457.5 | D4: 75 | F4: =C4+D4-E4 -> 532.5 | H4: 4029152167 | I4: BANRURAL
B5: AXEL ALVAREZ | C5: =+SUMIFS(Resumen_Semanal!F:F,Resumen_Semanal!B:B,Resumen_Semanal!B19) -> 495 | D5: =+(4*75) -> 300 | F5: =C5+D5-E5 -> 795 | G5: 2959555540613 | H5: 4029152135 | I5: BANRURAL
B6: BALDOMERO SOLANO | C6: =+SUMIFS(Resumen_Semanal!F:F,Resumen_Semanal!B:B,Resumen_Semanal!B14) -> 471.5 | D6: =+(4*75) -> 300 | F6: =C6+D6-E6 -> 771.5 | H6: 4029163700 | I6: BANRURAL
B7: CARLOS GARCIA | C7: =+SUMIFS(Resumen_Semanal!F:F,Resumen_Semanal!B:B,Resumen_Semanal!B12) -> 415.5 | D7: =+(4*75) -> 300 | F7: =C7+D7-E7 -> 715.5 | G7: 3099538120613 | H7: 4372143237 | I7: BANRURAL
B8: CARMELO GUAMUCH | C8: =+SUMIFS(Resumen_Semanal!F:F,Resumen_Semanal!B:B,Resumen_Semanal!B3) -> 503 | D8: =+(4*75) -> 300 | F8: =C8+D8-E8 -> 803 | G8: 3099783270613 | H8: 4029152098 | I8: BANRURAL
B9: DANILO SOLANO | C9: =+SUMIFS(Resumen_Semanal!F:F,Resumen_Semanal!B:B,Resumen_Semanal!B22) -> 426 | D9: 75 | F9: =C9+D9-E9 -> 501 | G9: 3098648870613 | H9: 4029152218 | I9: BANRURAL
B10: DIXON HERNANDEZ | C10: =+SUMIFS(Resumen_Semanal!F:F,Resumen_Semanal!B:B,Resumen_Semanal!B26) -> 353 | D10: 0 | F10: =C10+D10-E10 -> 353 | H10: 4029157433 | I10: BANRURAL
B11: EDGAR ROLANDO NAVAS | C11: =+SUMIFS(Resumen_Semanal!F:F,Resumen_Semanal!B:B,Resumen_Semanal!B8) -> 608 | D11: =+(4*75) -> 300 | F11: =C11+D11-E11 -> 908 | G11: 1706723600608 | H11: 4029152117 | I11: BANRURAL
B12: ELMER MANUEL HERNANDEZ | C12: =+SUMIFS(Resumen_Semanal!F:F,Resumen_Semanal!B:B,Resumen_Semanal!B17) -> 900 | D12: =+(4*75) -> 300 | F12: =C12+D12-E12 -> 1200 | G12: N/A | H12: 4029157520 | I12: BANRURAL
B13: ENMA PEREZ | C13: =+SUMIFS(Resumen_Semanal!F:F,Resumen_Semanal!B:B,Resumen_Semanal!B7) -> 536.5 | D13: =+(4*75) -> 300 | F13: =C13+D13-E13 -> 836.5 | G13: SE DEPOSITA A TONO | H13: 4029152070 | I13: BANRURAL
B14: FERNANDO GUAMUCH | C14: =+SUMIFS(Resumen_Semanal!F:F,Resumen_Semanal!B:B,Resumen_Semanal!B10) -> 528 | D14: =+(4*75) -> 300 | F14: =C14+D14-E14 -> 828 | G14: 2950209380613 | H14: 3029026021 | I14: BANRURAL
B15: FLORIDALMA ALVAREZ | C15: =+SUMIFS(Resumen_Semanal!F:F,Resumen_Semanal!B:B,Resumen_Semanal!B27) -> 557.5 | D15: 0 | F15: =C15+D15-E15 -> 557.5 | H15: 4029151948 | I15: BANRURAL
B16: FRANCISCO NAVAS | C16: =+SUMIFS(Resumen_Semanal!F:F,Resumen_Semanal!B:B,Resumen_Semanal!B24) -> 466.5 | D16: 75 | F16: =C16+D16-E16 -> 541.5 | G16: 3068027160601 | H16: 4029152218 | I16: BANRURAL
B17: GABY ALVAREZ | C17: =+SUMIFS(Resumen_Semanal!F:F,Resumen_Semanal!B:B,Resumen_Semanal!B30) -> 511.5 | D17: 75 | F17: =C17+D17-E17 -> 586.5 | H17: 4029152218 | I17: BANRURAL
B18: GERMAN SOLANO | C18: =+SUMIFS(Resumen_Semanal!F:F,Resumen_Semanal!B:B,Resumen_Semanal!B11) -> 510 | D18: =+(4*75) -> 300 | F18: =C18+D18-E18 -> 810 | G18: N/A | H18: 4396087194 | I18: BANRURAL
B19: HENRY RANDOLFO HERNANDEZ | C19: =+SUMIFS(Resumen_Semanal!F:F,Resumen_Semanal!B:B,Resumen_Semanal!B2) -> 1170 | D19: =400+700 -> 1100 | F19: =C19+D19-E19 -> 2270 | G19: 3099918620613 | H19: 4029152199 | I19: BANRURAL
B20: JAIME ANIBAL MARROQUIN | C20: =+SUMIFS(Resumen_Semanal!F:F,Resumen_Semanal!B:B,Resumen_Semanal!B5) -> 499.5 | D20: 300 | F20: =C20+D20-E20 -> 799.5 | G20: 3067692120601 | H20: 4372145336 | I20: BANRURAL
B21: JONATHAN AGUILAR | C21: =+SUMIFS(Resumen_Semanal!F:F,Resumen_Semanal!B:B,Resumen_Semanal!B18) -> 505.5 | D21: 75 | F21: =C21+D21-E21 -> 580.5 | G21: SE DEPOSITA A TONO | H21: 4029161954 | I21: BANRURAL
B22: JORGE MARROQUIN | C22: =+SUMIFS(Resumen_Semanal!F:F,Resumen_Semanal!B:B,Resumen_Semanal!B23) -> 422.5 | D22: 0 | F22: =C22+D22-E22 -> 422.5 | G22: SE DEPOSITA A TONO | H22: 4029159358 | I22: BANRURAL
B23: JORGE ODILIO SOLANO | C23: =+SUMIFS(Resumen_Semanal!F:F,Resumen_Semanal!B:B,Resumen_Semanal!B21) -> 531 | D23: 75 | F23: =C23+D23-E23 -> 606 | G23: 29595553380613 | H23: 4029152218 | I23: BANRURAL
B24: JULIA MARROQUIN | C24: =+SUMIFS(Resumen_Semanal!F:F,Resumen_Semanal!B:B,Resumen_Semanal!B13) -> 403.5 | D24: 300 | F24: =C24+D24-E24 -> 703.5 | G24: 1965763850613 | H24: 4029152153 | I24: BANRURAL
B25: LUZ DE MARIA MARTINEZ | C25: =+SUMIFS(Resumen_Semanal!F:F,Resumen_Semanal!B:B,Resumen_Semanal!B4) -> 501.5 | D25: 300 | F25: =C25+D25-E25 -> 801.5 | G25: 3100323690613 | H25: 4029152084 | I25: BANRURAL
B26: MARLENI SALAZAR | C26: =+SUMIFS(Resumen_Semanal!F:F,Resumen_Semanal!B:B,Resumen_Semanal!B20) -> 414 | D26: 75 | F26: =C26+D26-E26 -> 489 | G26: 2974713760613 | H26: 4029161922 | I26: BANRURAL
B27: NOHEMI ALVAREZ | C27: =+SUMIFS(Resumen_Semanal!F:F,Resumen_Semanal!B:B,Resumen_Semanal!B31) -> 473.5 | D27: 75 | F27: =C27+D27-E27 -> 548.5 | H27: 4029152218 | I27: BANRURAL
B28: OLIVER AGUILAR | C28: =+SUMIFS(Resumen_Semanal!F:F,Resumen_Semanal!B:B,Resumen_Semanal!B16) -> 536 | D28: 300 | F28: =C28+D28-E28 -> 836 | G28: 3423713632201 | H28: 4029157516 | I28: BANRURAL
B29: SULEIMA MARROQUIN | C29: =+SUMIFS(Resumen_Semanal!F:F,Resumen_Semanal!B:B,Resumen_Semanal!B9) -> 414 | D29: 300 | F29: =C29+D29-E29 -> 714 | G29: 1963954960613 | H29: 4029152218 | I29: BANRURAL
B30: SUSANA SOLANO | C30: =+SUMIFS(Resumen_Semanal!F:F,Resumen_Semanal!B:B,Resumen_Semanal!B6) -> 466.5 | D30: 300 | F30: =C30+D30-E30 -> 766.5 | G30: 3423713552201 | H30: 4029152149 | I30: BANRURAL
B31: TELMA HERNANDEZ | C31: =+SUMIFS(Resumen_Semanal!F:F,Resumen_Semanal!B:B,Resumen_Semanal!B29) -> 522.5 | D31: 75 | F31: =C31+D31-E31 -> 597.5 | H31: 4029152218 | I31: BANRURAL
B32: WILFRIDO HERNANDEZ | C32: =+SUMIFS(Resumen_Semanal!F:F,Resumen_Semanal!B:B,Resumen_Semanal!B28) -> 563 | D32: 75 | F32: =C32+D32-E32 -> 638 | H32: 4029152218 | I32: BANRURAL
B33: TOTAL A PAGAR | F33: =SUBTOTAL(109,Tabla3[Total a Pagar]) -> 22307.5 | J33: se estan pagando los dias de la semana santa
B36: Nombre Trabajador | C36: Total Devengado | D36: Bonificación | E36: Anticipos | F36: Total a Pagar | G36: DPI | H36: # DE CUENTA | I36: BANCO
B37: Marco Antonio Solano | C37: 2700 | D37: 150 | F37: =+Tabla4[[#This Row],[Total Devengado]]+Tabla4[[#This Row],[Bonificación]]-Tabla4[[#This Row],[Anticipos]] -> 2850 | G37: 1966179950608 | H37: 4029152218 | I37: BANRURAL
B38: Gildaberto Solano | C38: 1500 | D38: =400+700 -> 1100 | F38: =+Tabla4[[#This Row],[Total Devengado]]+Tabla4[[#This Row],[Bonificación]]-Tabla4[[#This Row],[Anticipos]] -> 2600 | H38: 4029112595 | I38: BANRURAL
B39: Alicia Yanet Morales | C39: =60*15 -> 900 | F39: =+Tabla4[[#This Row],[Total Devengado]]+Tabla4[[#This Row],[Bonificación]]-Tabla4[[#This Row],[Anticipos]] -> 900 | G39: 1977100930613 | H39: 4029143334 | I39: BANRURAL
B40: Keylin Yaneth Alvarez | C40: =17*60 -> 1020 | F40: =+Tabla4[[#This Row],[Total Devengado]]+Tabla4[[#This Row],[Bonificación]]-Tabla4[[#This Row],[Anticipos]] -> 1020 | G40: 3099918110613 | H40: 4029161904 | I40: BANRURAL
B41: GABY ALVAREZ | C41: =60*5 -> 300 | F41: =+Tabla4[[#This Row],[Total Devengado]]+Tabla4[[#This Row],[Bonificación]]-Tabla4[[#This Row],[Anticipos]] -> 300 | H41: 4029152218 | I41: BANRURAL
B42: NOHEMI ALVAREZ | C42: =60*4 -> 240 | F42: =+Tabla4[[#This Row],[Total Devengado]]+Tabla4[[#This Row],[Bonificación]]-Tabla4[[#This Row],[Anticipos]] -> 240 | H42: 4029152218 | I42: BANRURAL
...

Sheet Resumen_Lotes
A1: Semana | B1: Lote | C1: Total Devengado Lote
C2: =SUMAR.SI.CONJUNTO(Registro_Actividades!J:J,Registro_Actividades!F:F,B2,Registro_Actividades!B:B,A2) -> #NAME?
C3: =SUMAR.SI.CONJUNTO(Registro_Actividades!J:J,Registro_Actividades!F:F,B3,Registro_Actividades!B:B,A3) -> #NAME?
C4: =SUMAR.SI.CONJUNTO(Registro_Actividades!J:J,Registro_Actividades!F:F,B4,Registro_Actividades!B:B,A4) -> #NAME?
C5: =SUMAR.SI.CONJUNTO(Registro_Actividades!J:J,Registro_Actividades!F:F,B5,Registro_Actividades!B:B,A5) -> #NAME?
C6: =SUMAR.SI.CONJUNTO(Registro_Actividades!J:J,Registro_Actividades!F:F,B6,Registro_Actividades!B:B,A6) -> #NAME?
C7: =SUMAR.SI.CONJUNTO(Registro_Actividades!J:J,Registro_Actividades!F:F,B7,Registro_Actividades!B:B,A7) -> #NAME?
C8: =SUMAR.SI.CONJUNTO(Registro_Actividades!J:J,Registro_Actividades!F:F,B8,Registro_Actividades!B:B,A8) -> #NAME?
C9: =SUMAR.SI.CONJUNTO(Registro_Actividades!J:J,Registro_Actividades!F:F,B9,Registro_Actividades!B:B,A9) -> #NAME?
C10: =SUMAR.SI.CONJUNTO(Registro_Actividades!J:J,Registro_Actividades!F:F,B10,Registro_Actividades!B:B,A10) -> #NAME?
C11: =SUMAR.SI.CONJUNTO(Registro_Actividades!J:J,Registro_Actividades!F:F,B11,Registro_Actividades!B:B,A11) -> #NAME?
C12: =SUMAR.SI.CONJUNTO(Registro_Actividades!J:J,Registro_Actividades!F:F,B12,Registro_Actividades!B:B,A12) -> #NAME?
C13: =SUMAR.SI.CONJUNTO(Registro_Actividades!J:J,Registro_Actividades!F:F,B13,Registro_Actividades!B:B,A13) -> #NAME?
... C51: =SUMAR.SI.CONJUNTO(Registro_Actividades!J:J,Registro_Actividades!F:F,B51,Registro_Actividades!B:B,A51) -> #NAME?
