Workbook

Sheet Registro_Actividades
A1: Fecha | B1: Semana | C1: Nombre Trabajador | D1: DPI | E1: Actividad | F1: Lote | G1: Unidad | H1: Cantidad | I1: Precio Unitario | J1: Total Devengado
A2: 46066 | B2: =_xlfn.SINGLE(WEEKNUM(A2,2)) -> 7 | C2: GILDABERTO SOLANO | E2: Caporal | F2: Canoa | G2: =IFERROR(VLOOKUP(E2,Control_Actividades!A:C,2,FALSE),"") -> Dia | H2: 1 | I2: =IFERROR(VLOOKUP(E2,Control_Actividades!A:C,3,FALSE),"") -> 100 | J2: =H2*I2 -> 100
A3: 46066 | B3: =WEEKNUM(A3,2) -> 7 | C3: HENRY RANDOLFO HERNANDEZ | E3: encargado beneficio | F3: beneficio | G3: =IFERROR(VLOOKUP(E3,Control_Actividades!A:C,2,FALSE),"") -> Dia | H3: 1.35 | I3: =IFERROR(VLOOKUP(E3,Control_Actividades!A:C,3,FALSE),"") -> 130 | J3: =H3*I3 -> 175.5
A4: 46066 | B4: =_xlfn.SINGLE(WEEKNUM(A4,2)) -> 7 | C4: CARMELO GUAMUCH | E4: Beneficio | F4: beneficio | G4: =IFERROR(VLOOKUP(E4,Control_Actividades!A:C,2,FALSE),"") -> Dia | H4: 1 | I4: =IFERROR(VLOOKUP(E4,Control_Actividades!A:C,3,FALSE),"") -> 100 | J4: =H4*I4 -> 100
A5: 46066 | B5: =WEEKNUM(A5,2) -> 7 | C5: LUZ DE MARIA MARTINEZ | E5: Corte de Café | F5: Canoa | G5: =IFERROR(VLOOKUP(E5,Control_Actividades!A:C,2,FALSE),"") -> Quintal | H5: 1.5 | I5: =IFERROR(VLOOKUP(E5,Control_Actividades!A:C,3,FALSE),"") -> 70 | J5: =H5*I5 -> 105
A6: 46066 | B6: =_xlfn.SINGLE(WEEKNUM(A6,2)) -> 7 | C6: JAIME ANIBAL MARROQUIN | E6: Corte de Café | F6: Canoa | G6: =IFERROR(VLOOKUP(E6,Control_Actividades!A:C,2,FALSE),"") -> Quintal | H6: 1.35 | I6: =IFERROR(VLOOKUP(E6,Control_Actividades!A:C,3,FALSE),"") -> 70 | J6: =H6*I6 -> 94.5
A7: 46066 | B7: =WEEKNUM(A7,2) -> 7 | C7: SUSANA SOLANO | E7: Corte de Café | F7: Canoa | G7: =IFERROR(VLOOKUP(E7,Control_Actividades!A:C,2,FALSE),"") -> Quintal | H7: 1.1 | I7: =IFERROR(VLOOKUP(E7,Control_Actividades!A:C,3,FALSE),"") -> 70 | J7: =H7*I7 -> 77
A8: 46066 | B8: =_xlfn.SINGLE(WEEKNUM(A8,2)) -> 7 | C8: ENMA PEREZ | E8: Corte de Café | F8: Canoa | G8: =IFERROR(VLOOKUP(E8,Control_Actividades!A:C,2,FALSE),"") -> Quintal | H8: 1.65 | I8: =IFERROR(VLOOKUP(E8,Control_Actividades!A:C,3,FALSE),"") -> 70 | J8: =H8*I8 -> 115.5
A9: 46066 | B9: =WEEKNUM(A9,2) -> 7 | C9: EDGAR ROLANDO NAVAS | E9: Caporal | F9: Canoa | G9: =IFERROR(VLOOKUP(E9,Control_Actividades!A:C,2,FALSE),"") -> Dia | H9: 1 | I9: =IFERROR(VLOOKUP(E9,Control_Actividades!A:C,3,FALSE),"") -> 100 | J9: =H9*I9 -> 100
A10: 46066 | B10: =_xlfn.SINGLE(WEEKNUM(A10,2)) -> 7 | C10: SULEIMA MARROQUIN | E10: Corte de Café | F10: Canoa | G10: =IFERROR(VLOOKUP(E10,Control_Actividades!A:C,2,FALSE),"") -> Quintal | H10: 1.15 | I10: =IFERROR(VLOOKUP(E10,Control_Actividades!A:C,3,FALSE),"") -> 70 | J10: =H10*I10 -> 80.5
A11: 46066 | B11: =WEEKNUM(A11,2) -> 7 | C11: FERNANDO GUAMUCH | E11: Corte de Café | F11: Canoa | G11: =IFERROR(VLOOKUP(E11,Control_Actividades!A:C,2,FALSE),"") -> Quintal | H11: 1.1 | I11: =IFERROR(VLOOKUP(E11,Control_Actividades!A:C,3,FALSE),"") -> 70 | J11: =H11*I11 -> 77
A12: 46066 | B12: =_xlfn.SINGLE(WEEKNUM(A12,2)) -> 7 | C12: GERMAN SOLANO | E12: Poda | F12: Cruz 2 | G12: =IFERROR(VLOOKUP(E12,Control_Actividades!A:C,2,FALSE),"") -> Manzana | H12: 2 | I12: =IFERROR(VLOOKUP(E12,Control_Actividades!A:C,3,FALSE),"") -> 110 | J12: =H12*I12 -> 220
A13: 46066 | B13: =WEEKNUM(A13,2) -> 7 | C13: CARLOS GARCIA | E13: Corte de Café | F13: Canoa | G13: =IFERROR(VLOOKUP(E13,Control_Actividades!A:C,2,FALSE),"") -> Quintal | H13: 1.35 | I13: =IFERROR(VLOOKUP(E13,Control_Actividades!A:C,3,FALSE),"") -> 70 | J13: =H13*I13 -> 94.5
A14: 46066 | B14: =_xlfn.SINGLE(WEEKNUM(A14,2)) -> 7 | C14: JULIA MARROQUIN | E14: Corte de Café | F14: Canoa | G14: =IFERROR(VLOOKUP(E14,Control_Actividades!A:C,2,FALSE),"") -> Quintal | H14: 1.35 | I14: =IFERROR(VLOOKUP(E14,Control_Actividades!A:C,3,FALSE),"") -> 70 | J14: =H14*I14 -> 94.5
A15: 46066 | B15: =WEEKNUM(A15,2) -> 7 | C15: BALDOMERO SOLANO | E15: Corte de Café | F15: Canoa | G15: =IFERROR(VLOOKUP(E15,Control_Actividades!A:C,2,FALSE),"") -> Quintal | H15: 1.1 | I15: =IFERROR(VLOOKUP(E15,Control_Actividades!A:C,3,FALSE),"") -> 70 | J15: =H15*I15 -> 77
A16: 46066 | B16: =_xlfn.SINGLE(WEEKNUM(A16,2)) -> 7 | C16: ADISTER ARCENIO | G16: =IFERROR(VLOOKUP(E16,Control_Actividades!A:C,2,FALSE),"") | I16: =IFERROR(VLOOKUP(E16,Control_Actividades!A:C,3,FALSE),"") | J16: =H16*I16 -> #VALUE!
A17: 46066 | B17: =WEEKNUM(A17,2) -> 7 | C17: OLIVER AGUILAR | E17: Corte de Café | F17: Canoa | G17: =IFERROR(VLOOKUP(E17,Control_Actividades!A:C,2,FALSE),"") -> Quintal | H17: 1.1 | I17: =IFERROR(VLOOKUP(E17,Control_Actividades!A:C,3,FALSE),"") -> 70 | J17: =H17*I17 -> 77
A18: 46066 | B18: =_xlfn.SINGLE(WEEKNUM(A18,2)) -> 7 | C18: ELMER MANUEL HERNANDEZ | E18: Beneficio | F18: beneficio | G18: =IFERROR(VLOOKUP(E18,Control_Actividades!A:C,2,FALSE),"") -> Dia | H18: 1 | I18: =IFERROR(VLOOKUP(E18,Control_Actividades!A:C,3,FALSE),"") -> 100 | J18: =H18*I18 -> 100
A19: 46066 | B19: =WEEKNUM(A19,2) -> 7 | C19: IRIS PEREZ | E19: Corte de Café | F19: Canoa | G19: =IFERROR(VLOOKUP(E19,Control_Actividades!A:C,2,FALSE),"") -> Quintal | H19: 1.75 | I19: =IFERROR(VLOOKUP(E19,Control_Actividades!A:C,3,FALSE),"") -> 70 | J19: =H19*I19 -> 122.5
A20: 46066 | B20: =_xlfn.SINGLE(WEEKNUM(A20,2)) -> 7 | C20: JONATHAN AGUILAR | E20: Beneficio | F20: beneficio | G20: =IFERROR(VLOOKUP(E20,Control_Actividades!A:C,2,FALSE),"") -> Dia | H20: 1 | I20: =IFERROR(VLOOKUP(E20,Control_Actividades!A:C,3,FALSE),"") -> 100 | J20: =H20*I20 -> 100
A21: 46066 | B21: =WEEKNUM(A21,2) -> 7 | C21: AXEL ALVAREZ | E21: Beneficio | F21: beneficio | G21: =IFERROR(VLOOKUP(E21,Control_Actividades!A:C,2,FALSE),"") -> Dia | H21: 1 | I21: =IFERROR(VLOOKUP(E21,Control_Actividades!A:C,3,FALSE),"") -> 100 | J21: =H21*I21 -> 100
A22: 46066 | B22: =_xlfn.SINGLE(WEEKNUM(A22,2)) -> 7 | C22: MARLENI SALAZAR | E22: Corte de Café | F22: Canoa | G22: =IFERROR(VLOOKUP(E22,Control_Actividades!A:C,2,FALSE),"") -> Quintal | H22: 1 | I22: =IFERROR(VLOOKUP(E22,Control_Actividades!A:C,3,FALSE),"") -> 70 | J22: =H22*I22 -> 70
A23: 46066 | B23: =WEEKNUM(A23,2) -> 7 | C23: JORGE ODILIO SOLANO | E23: Corte de Café | F23: Canoa | G23: =IFERROR(VLOOKUP(E23,Control_Actividades!A:C,2,FALSE),"") -> Quintal | H23: 1.2 | I23: =IFERROR(VLOOKUP(E23,Control_Actividades!A:C,3,FALSE),"") -> 70 | J23: =H23*I23 -> 84
A24: 46066 | B24: =_xlfn.SINGLE(WEEKNUM(A24,2)) -> 7 | C24: DANILO SOLANO | E24: Corte de Café | F24: Canoa | G24: =IFERROR(VLOOKUP(E24,Control_Actividades!A:C,2,FALSE),"") -> Quintal | H24: 0.85 | I24: =IFERROR(VLOOKUP(E24,Control_Actividades!A:C,3,FALSE),"") -> 70 | J24: =H24*I24 -> 59.5
A25: 46067 | B25: =WEEKNUM(A25,2) -> 7 | C25: GILDABERTO SOLANO | E25: Caporal | F25: Canoa | G25: =IFERROR(VLOOKUP(E25,Control_Actividades!A:C,2,FALSE),"") -> Dia | H25: 1 | I25: =IFERROR(VLOOKUP(E25,Control_Actividades!A:C,3,FALSE),"") -> 100 | J25: =H25*I25 -> 100
A26: 46067 | B26: =_xlfn.SINGLE(WEEKNUM(A26,2)) -> 7 | C26: HENRY RANDOLFO HERNANDEZ | E26: Encargado beneficio | F26: beneficio | G26: =IFERROR(VLOOKUP(E26,Control_Actividades!A:C,2,FALSE),"") -> Dia | H26: 1 | I26: =IFERROR(VLOOKUP(E26,Control_Actividades!A:C,3,FALSE),"") -> 130 | J26: =H26*I26 -> 130
A27: 46067 | B27: =WEEKNUM(A27,2) -> 7 | C27: CARMELO GUAMUCH | G27: =IFERROR(VLOOKUP(E27,Control_Actividades!A:C,2,FALSE),"") | I27: =IFERROR(VLOOKUP(E27,Control_Actividades!A:C,3,FALSE),"") | J27: =H27*I27 -> #VALUE!
A28: 46067 | B28: =_xlfn.SINGLE(WEEKNUM(A28,2)) -> 7 | C28: LUZ DE MARIA MARTINEZ | G28: =IFERROR(VLOOKUP(E28,Control_Actividades!A:C,2,FALSE),"") | I28: =IFERROR(VLOOKUP(E28,Control_Actividades!A:C,3,FALSE),"") | J28: =H28*I28 -> #VALUE!
A29: 46067 | B29: =WEEKNUM(A29,2) -> 7 | C29: JAIME ANIBAL MARROQUIN | E29: Corte de Café | F29: Canoa | G29: =IFERROR(VLOOKUP(E29,Control_Actividades!A:C,2,FALSE),"") -> Quintal | H29: 0.65 | I29: =IFERROR(VLOOKUP(E29,Control_Actividades!A:C,3,FALSE),"") -> 70 | J29: =H29*I29 -> 45.5
A30: 46067 | B30: =_xlfn.SINGLE(WEEKNUM(A30,2)) -> 7 | C30: SUSANA SOLANO | G30: =IFERROR(VLOOKUP(E30,Control_Actividades!A:C,2,FALSE),"") | I30: =IFERROR(VLOOKUP(E30,Control_Actividades!A:C,3,FALSE),"") | J30: =H30*I30 -> #VALUE!
A31: 46067 | B31: =WEEKNUM(A31,2) -> 7 | C31: ENMA PEREZ | G31: =IFERROR(VLOOKUP(E31,Control_Actividades!A:C,2,FALSE),"") | I31: =IFERROR(VLOOKUP(E31,Control_Actividades!A:C,3,FALSE),"") | J31: =H31*I31 -> #VALUE!
A32: 46067 | B32: =_xlfn.SINGLE(WEEKNUM(A32,2)) -> 7 | C32: EDGAR ROLANDO NAVAS | E32: Beneficio | F32: beneficio | G32: =IFERROR(VLOOKUP(E32,Control_Actividades!A:C,2,FALSE),"") -> Dia | H32: 1 | I32: =IFERROR(VLOOKUP(E32,Control_Actividades!A:C,3,FALSE),"") -> 100 | J32: =H32*I32 -> 100
A33: 46067 | B33: =WEEKNUM(A33,2) -> 7 | C33: SULEIMA MARROQUIN | E33: Corte de Café | F33: Canoa | G33: =IFERROR(VLOOKUP(E33,Control_Actividades!A:C,2,FALSE),"") -> Quintal | H33: 0.55 | I33: =IFERROR(VLOOKUP(E33,Control_Actividades!A:C,3,FALSE),"") -> 70 | J33: =H33*I33 -> 38.5
A34: 46067 | B34: =_xlfn.SINGLE(WEEKNUM(A34,2)) -> 7 | C34: FERNANDO GUAMUCH | G34: =IFERROR(VLOOKUP(E34,Control_Actividades!A:C,2,FALSE),"") | I34: =IFERROR(VLOOKUP(E34,Control_Actividades!A:C,3,FALSE),"") | J34: =H34*I34 -> #VALUE!
A35: 46067 | B35: =WEEKNUM(A35,2) -> 7 | C35: GERMAN SOLANO | E35: Poda | F35: Cruz 2 | G35: =IFERROR(VLOOKUP(E35,Control_Actividades!A:C,2,FALSE),"") -> Manzana | H35: 2 | I35: =IFERROR(VLOOKUP(E35,Control_Actividades!A:C,3,FALSE),"") -> 110 | J35: =H35*I35 -> 220
A36: 46067 | B36: =_xlfn.SINGLE(WEEKNUM(A36,2)) -> 7 | C36: CARLOS GARCIA | E36: Corte de Café | F36: Canoa | G36: =IFERROR(VLOOKUP(E36,Control_Actividades!A:C,2,FALSE),"") -> Quintal | H36: 0.55 | I36: =IFERROR(VLOOKUP(E36,Control_Actividades!A:C,3,FALSE),"") -> 70 | J36: =H36*I36 -> 38.5
A37: 46067 | B37: =WEEKNUM(A37,2) -> 7 | C37: JULIA MARROQUIN | E37: Corte de Café | F37: Canoa | G37: =IFERROR(VLOOKUP(E37,Control_Actividades!A:C,2,FALSE),"") -> Quintal | H37: 0.95 | I37: =IFERROR(VLOOKUP(E37,Control_Actividades!A:C,3,FALSE),"") -> 70 | J37: =H37*I37 -> 66.5
A38: 46067 | B38: =_xlfn.SINGLE(WEEKNUM(A38,2)) -> 7 | C38: BALDOMERO SOLANO | E38: Corte de Café | F38: Canoa | G38: =IFERROR(VLOOKUP(E38,Control_Actividades!A:C,2,FALSE),"") -> Quintal | H38: 0.85 | I38: =IFERROR(VLOOKUP(E38,Control_Actividades!A:C,3,FALSE),"") -> 70 | J38: =H38*I38 -> 59.5
A39: 46067 | B39: =WEEKNUM(A39,2) -> 7 | C39: ADISTER ARCENIO | E39: Poda | F39: Cruz 2 | G39: =IFERROR(VLOOKUP(E39,Control_Actividades!A:C,2,FALSE),"") -> Manzana | H39: 1.33 | I39: =IFERROR(VLOOKUP(E39,Control_Actividades!A:C,3,FALSE),"") -> 110 | J39: =H39*I39 -> 146.3
A40: 46067 | B40: =_xlfn.SINGLE(WEEKNUM(A40,2)) -> 7 | C40: OLIVER AGUILAR | G40: =IFERROR(VLOOKUP(E40,Control_Actividades!A:C,2,FALSE),"") | I40: =IFERROR(VLOOKUP(E40,Control_Actividades!A:C,3,FALSE),"") | J40: =H40*I40 -> #VALUE!
...

Sheet Control_Actividades
A1: Actividad | B1: Unidad | C1: Precio Unitario
A2: Corte de Café | B2: Quintal | C2: 70
A3: Pepena | B3: Quintal | C3: 0
A4: Fertilización | B4: Hectárea | C4: 150
A5: Limpia Manual | B5: Jornal | C5: 50
A6: Poda | B6: Manzana | C6: 110
A7: Caporal | B7: Dia | C7: 100
A8: Beneficio | B8: Dia | C8: 100
A9: Encargado Beneficio | B9: Dia | C9: 130
A10: Muestreo de Suelos | B10: Dia | C10: 75
A11: Repaso Poda | B11: Manzana | C11: 100

Sheet Resumen_Semanal
A1: Semana | B1: Nombre Trabajador | C1: Total Devengado | D1: Bonificación | E1: Anticipos | F1: Total a Pagar
C2: =SUMAR.SI.CONJUNTO(Registro_Actividades!J:J,Registro_Actividades!C:C,B2,Registro_Actividades!B:B,A2) -> #NAME? | F2: =C2+D2-E2 -> #NAME?
C3: =SUMAR.SI.CONJUNTO(Registro_Actividades!J:J,Registro_Actividades!C:C,B3,Registro_Actividades!B:B,A3) -> #NAME? | F3: =C3+D3-E3 -> #NAME?
C4: =SUMAR.SI.CONJUNTO(Registro_Actividades!J:J,Registro_Actividades!C:C,B4,Registro_Actividades!B:B,A4) -> #NAME? | F4: =C4+D4-E4 -> #NAME?
C5: =SUMAR.SI.CONJUNTO(Registro_Actividades!J:J,Registro_Actividades!C:C,B5,Registro_Actividades!B:B,A5) -> #NAME? | F5: =C5+D5-E5 -> #NAME?
C6: =SUMAR.SI.CONJUNTO(Registro_Actividades!J:J,Registro_Actividades!C:C,B6,Registro_Actividades!B:B,A6) -> #NAME? | F6: =C6+D6-E6 -> #NAME?
C7: =SUMAR.SI.CONJUNTO(Registro_Actividades!J:J,Registro_Actividades!C:C,B7,Registro_Actividades!B:B,A7) -> #NAME? | F7: =C7+D7-E7 -> #NAME?
C8: =SUMAR.SI.CONJUNTO(Registro_Actividades!J:J,Registro_Actividades!C:C,B8,Registro_Actividades!B:B,A8) -> #NAME? | F8: =C8+D8-E8 -> #NAME?
C9: =SUMAR.SI.CONJUNTO(Registro_Actividades!J:J,Registro_Actividades!C:C,B9,Registro_Actividades!B:B,A9) -> #NAME? | F9: =C9+D9-E9 -> #NAME?
C10: =SUMAR.SI.CONJUNTO(Registro_Actividades!J:J,Registro_Actividades!C:C,B10,Registro_Actividades!B:B,A10) -> #NAME? | F10: =C10+D10-E10 -> #NAME?
C11: =SUMAR.SI.CONJUNTO(Registro_Actividades!J:J,Registro_Actividades!C:C,B11,Registro_Actividades!B:B,A11) -> #NAME? | F11: =C11+D11-E11 -> #NAME?
C12: =SUMAR.SI.CONJUNTO(Registro_Actividades!J:J,Registro_Actividades!C:C,B12,Registro_Actividades!B:B,A12) -> #NAME? | F12: =C12+D12-E12 -> #NAME?
C13: =SUMAR.SI.CONJUNTO(Registro_Actividades!J:J,Registro_Actividades!C:C,B13,Registro_Actividades!B:B,A13) -> #NAME? | F13: =C13+D13-E13 -> #NAME?
... C51: =SUMAR.SI.CONJUNTO(Registro_Actividades!J:J,Registro_Actividades!C:C,B51,Registro_Actividades!B:B,A51) -> #NAME? | F51: =C51+D51-E51 -> #NAME?

Sheet Resumen_Lotes
A1: Semana | B1: Lote | C1: Total Devengado Lote
C2: =SUMAR.SI.CONJUNTO(Registro_Actividades!J:J,Registro_Actividades!F:F,B2,Registro_Actividades!B:B,A2) -> #NAME?
C3: =SUMAR.SI.CONJUNTO(Registro_Actividades!J:J,Registro_Actividades!F:F,B3,Registro_Actividades!B:B,A3) -> #NAME?
C4: =SUMAR.SI.CONJUNTO(Registro_Actividades!J:J,Registro_Actividades!F:F,B4,Registro_Actividades!B:B,A4) -> #NAME?
C5: =SUMAR.SI.CONJUNTO(Registro_Actividades!J:J,Registro_Actividades!F:F,B5,Registro_Actividades!B:B,A5) -> #NAME?
C6: =SUMAR.SI.CONJUNTO(Registro_Actividades!J:J,Registro_Actividades!F:F,B6,Registro_Actividades!B:B,A6) -> #NAME?
C7: =SUMAR.SI.CONJUNTO(Registro_Actividades!J:J,Registro_Actividades!F:F,B7,Registro_Actividades!B:B,A7) -> #NAME?
C8: =SUMAR.SI.CONJUNTO(Registro_Actividades!J:J,Registro_Actividades!F:F,B8,Registro_Actividades!B:B,A8) -> #NAME?
C9: =SUMAR.SI.CONJUNTO(Registro_Actividades!J:J,Registro_Actividades!F:F,B9,Registro_Actividades!B:B,A9) -> #NAME?
C10: =SUMAR.SI.CONJUNTO(Registro_Actividades!J:J,Registro_Actividades!F:F,B10,Registro_Actividades!B:B,A10) -> #NAME?
C11: =SUMAR.SI.CONJUNTO(Registro_Actividades!J:J,Registro_Actividades!F:F,B11,Registro_Actividades!B:B,A11) -> #NAME?
C12: =SUMAR.SI.CONJUNTO(Registro_Actividades!J:J,Registro_Actividades!F:F,B12,Registro_Actividades!B:B,A12) -> #NAME?
C13: =SUMAR.SI.CONJUNTO(Registro_Actividades!J:J,Registro_Actividades!F:F,B13,Registro_Actividades!B:B,A13) -> #NAME?
... C51: =SUMAR.SI.CONJUNTO(Registro_Actividades!J:J,Registro_Actividades!F:F,B51,Registro_Actividades!B:B,A51) -> #NAME?
