Workbook

Sheet DATA MANUEL FLORES
A2: # | B2: FECHA | C2: 46125 | F2: 46126 | I2: 46127 | L2: 46128 | O2: 46129 | R2: 46130
B3: Trabajador | C3: Lote | D3: Actividad | E3: Unidades | F3: Lote | G3: Actividad | H3: Unidades | I3: Lote | J3: Actividad | K3: Unidades | L3: Lote | M3: Actividad | N3: Unidades | O3: Lote | P3: Actividad | Q3: Unidades | R3: Lote | S3: Actividad | T3: Unidades
A4: 1 | B4: Marco Antonio Solano | C4: CP | D4: CP | E4: 1 | F4: CP | G4: CP | H4: 1 | I4: CP | J4: CP | K4: 1 | L4: CP | M4: CP | N4: 1 | O4: CP | P4: CP | Q4: 1 | R4: CP | S4: CP | T4: 1
A5: 2 | B5: Gildaberto Solano Arenas | C5: CP | D5: CP | E5: 1 | F5: CP | G5: CP | H5: 1 | I5: CP | J5: CP | K5: 1 | L5: CP | M5: CP | N5: 1 | O5: CP | P5: CP | Q5: 1 | R5: CP | S5: CP | T5: 1
A6: 3 | B6: Henry Randolfo Hernandez Solano | C6: CASA | D6: BE | E6: 1 | F6: BE | G6: BE | H6: 1 | I6: CASA | J6: BE | K6: 1 | L6: BE | M6: BE | N6: 1 | O6: BE | P6: BE | Q6: 1 | R6: BE | S6: BE | T6: 1
A7: 4 | B7: Ruth Nohemi Alvarez Jimenez | C7: CASA | D7: MG | E7: 1 | F7: CASA | G7: MG | H7: 1 | I7: CASA | J7: MG | K7: 1 | L7: CASA | M7: MG | N7: 1 | O7: CASA | P7: MG | Q7: 1 | R7: CASA | S7: MG | T7: 1
A8: 5 | B8: Gaby Maidely Alvarez Jimenez | C8: MG | D8: MG | E8: 1 | F8: CASA | G8: MG | H8: 1 | I8: MG | J8: MG | K8: 1 | L8: CASA | M8: MG | N8: 1 | O8: MG | P8: MG | Q8: 1 | R8: MG | S8: MG | T8: 1
A9: 6 | B9: Enma Mannolia Perez Najera | C9: CANOA | D9: LL | E9: 1 | F9: ARENERA | G9: RP | H9: 1 | I9: CAÑADA | J9: RP | K9: 1 | L9: SAN EMILIANO | M9: RP | N9: 1 | O9: SAN EMILIANO | P9: RP | Q9: 1 | R9: CANOA | S9: LL | T9: 1
A10: 7 | B10: German Nolberto Solano Marroquin | C10: CANOA | D10: LL | E10: 1 | F10: CAÑADA | G10: RP | H10: 1 | I10: CAÑADA | J10: RP | K10: 1 | L10: CANOA | M10: LL | N10: 1 | O10: CANOA | P10: RP | Q10: 1 | R10: CANOA | S10: LL | T10: 1
A11: 8 | B11: Jaime Anibal Marroquin Salazar | C11: CANOA | D11: LL | E11: 1 | F11: CAÑADA | G11: RP | H11: 1 | I11: CAÑADA | J11: RP | K11: 1 | L11: CANOA | M11: LL | N11: 1 | O11: CANOA | P11: RP | Q11: 1 | R11: CANOA | S11: LL | T11: 1
A12: 9 | B12: Adister Arcenio Marroquin | C12: SAN EMILIANO | D12: RP | E12: 1 | F12: SAN EMILIANO | G12: RP | H12: 1 | I12: SAN EMILIANO | J12: RP | K12: 1 | L12: SAN EMILIANO | M12: RP | N12: 1 | O12: CAÑADA | P12: RP | Q12: 0.5 | R12: CRUZ 1 | S12: RP | T12: 1.5
A13: 10 | B13: Edgar Rolando Navas Chacon | I13: CAÑADA | J13: RP | K13: 1 | L13: SAN EMILIANO | M13: RP | N13: 1 | O13: SAN EMILIANO | P13: RP | Q13: 1 | R13: CANOA | S13: LL | T13: 1
A14: 11 | B14: Cindy Roxana Alvarez Lopez
A15: 12 | B15: Carmelo Marroquin Salazar | C15: CANOA | D15: LL | E15: 1 | F15: CAÑADA | G15: RP | H15: 1 | I15: CAÑADA | J15: RP | K15: 1 | L15: CANOA | M15: LL | N15: 1
A16: 13 | B16: Erick Ronaldo Hernandez Martinez
A17: 14 | B17: Erica Yanira Alvarez Lopez
A18: 15 | B18: Elmer Alexander Hernandez Raliois | C18: BE | D18: BE | E18: 1 | F18: BN | G18: BN | H18: 1 | I18: BN | J18: BN | K18: 1 | L18: BN | M18: BN | N18: 1 | O18: BN | P18: BN | Q18: 1 | R18: BN | S18: BN | T18: 1
A19: 16 | B19: Axel Amildo Alvarez Morales | C19: SAN EMILIANO | D19: RP | E19: 1 | F19: SAN EMILIANO | G19: RP | H19: 1 | I19: SAN EMILIANO | J19: RP | K19: 1 | L19: SAN EMILIANO | M19: RP | N19: 1 | O19: CAÑADA | P19: RP | Q19: 1 | R19: CRUZ 1 | S19: RP | T19: 1.5
A20: 17 | B20: Carlos Albino Garcia Mendez | F20: CAÑADA | G20: RP | H20: 1 | I20: CAÑADA | J20: RP | K20: 1 | L20: CANOA | M20: LL | N20: 1 | O20: CANOA | P20: RP | Q20: 1
A21: 18 | B21: Dixon Rene Hernandez Martinez | F21: CAÑADA | G21: RP | H21: 1 | I21: CAÑADA | J21: RP | K21: 1 | L21: CANOA | M21: LL | N21: 1 | O21: CANOA | P21: RP | Q21: 1 | R21: CANOA | S21: LL | T21: 1
A22: 19 | B22: Jose Alexander Navas Martinez | C22: CANOA | D22: LL | E22: 1 | F22: CAÑADA | G22: RP | H22: 1 | R22: CANOA | S22: LL | T22: 1
A23: 20 | B23: Wilfrido Hernandez Ralios | F23: CAÑADA | G23: RP | H23: 1 | I23: CAÑADA | J23: RP | K23: 1 | L23: CANOA | M23: LL | N23: 1 | O23: CANOA | P23: RP | Q23: 1 | R23: CANOA | S23: LL | T23: 1
A24: 21 | B24: Yaritza Amarilis Navas Sanchez | C24: CANOA | D24: LL | E24: 1 | I24: CAÑADA | J24: RP | K24: 1 | L24: SAN EMILIANO | M24: RP | N24: 1 | O24: SAN EMILIANO | P24: RP | Q24: 1 | R24: CANOA | S24: LL | T24: 1
A25: 22 | B25: Luz De Maria Martinez Solano | C25: CANOA | D25: LL | E25: 1 | F25: ARENERA | G25: RP | H25: 1 | I25: ARENERA | J25: RP | K25: 1 | L25: SAN EMILIANO | M25: RP | N25: 1 | O25: SAN EMILIANO | P25: RP | Q25: 1 | R25: CANOA | S25: LL | T25: 1
A26: 23 | B26: Telma Elizabeth Hernandez Martinez | C26: CANOA | D26: LL | E26: 1 | F26: ARENERA | G26: RP | H26: 1 | I26: CAÑADA | J26: RP | K26: 1 | L26: SAN EMILIANO | M26: RP | N26: 1 | O26: SAN EMILIANO | P26: RP | Q26: 1 | R26: CANOA | S26: LL | T26: 1
A27: 24 | B27: Elderr Eduardo Hernandez Navas | C27: CANOA | D27: LL | E27: 1 | I27: CAÑADA | J27: RP | K27: 1 | L27: CANOA | M27: LL | N27: 1 | O27: CANOA | P27: LL | Q27: 1 | R27: CANOA | S27: LL | T27: 1
A28: 25 | B28: Francisco Alexander Navas Juarez | C28: CANOA | D28: LL | E28: 1 | F28: CAÑADA | G28: RP | H28: 1 | R28: CANOA | S28: LL | T28: 1
A29: 26 | B29: Fernando Adelder Guamush Perez | C29: CANOA | D29: LL | E29: 1 | F29: CAÑADA | G29: RP | H29: 1 | I29: CAÑADA | J29: RP | K29: 1 | L29: CANOA | M29: LL | N29: 1 | O29: CANOA | P29: LL | Q29: 1 | R29: CANOA | S29: LL | T29: 1
A30: 27 | B30: Jorge Luis Marroquin Salazar | C30: CANOA | D30: LL | E30: 1 | F30: CAÑADA | G30: RP | H30: 1 | I30: CAÑADA | J30: RP | K30: 1 | L30: CANOA | M30: LL | N30: 1
A31: 28 | B31: Baldomero Solano Marroquin | C31: CANOA | D31: LL | E31: 1 | F31: CAÑADA | G31: RP | H31: 1 | I31: CAÑADA | J31: RP | K31: 1 | L31: CANOA | M31: LL | N31: 1 | O31: CANOA | P31: LL | Q31: 1 | R31: CANOA | S31: LL | T31: 1
A32: 29 | B32: Leidy Susana Solano Perez | C32: CANOA | D32: LL | E32: 1 | F32: ARENERA | G32: RP | H32: 1 | I32: CAÑADA | J32: RP | K32: 1 | L32: SAN EMILIANO | M32: RP | N32: 1 | O32: SAN EMILIANO | P32: RP | Q32: 1 | R32: CANOA | S32: LL | T32: 1
A33: 30 | B33: Jorge Odilio Solano Marroquin | C33: CANOA | D33: LL | E33: 1 | F33: CAÑADA | G33: RP | H33: 1 | I33: CAÑADA | J33: LL | K33: 1 | L33: CANOA | M33: LL | N33: 1 | O33: CANOA | P33: LL | Q33: 1 | R33: CANOA | S33: LL | T33: 1
A34: 31 | B34: Maria Floridalma Alvarez Morales | C34: CANOA | D34: LL | E34: 1 | F34: ARENERA | G34: RP | H34: 1 | I34: CAÑADA | J34: RP | K34: 1 | L34: SAN EMILIANO | M34: RP | N34: 1 | O34: SAN EMILIANO | P34: RP | Q34: 1 | R34: CANOA | S34: LL | T34: 1
A35: 32 | B35: Oliver Gerardo Aguilar Sanchez | C35: CANOA | D35: LL | E35: 1 | F35: CAÑADA | G35: RP | H35: 1 | I35: CAÑADA | J35: RP | K35: 1 | L35: CANOA | M35: LL | N35: 1 | O35: CANOA | P35: LL | Q35: 1 | R35: CANOA | S35: LL | T35: 1
A36: 33 | B36: Julia Yanira Marroquin | C36: CANOA | D36: LL | E36: 1 | F36: ARENERA | G36: RP | H36: 1 | I36: CAÑADA | J36: RP | K36: 1 | L36: SAN EMILIANO | M36: RP | N36: 1 | O36: CANOA | P36: LL | Q36: 1
A37: 34 | B37: Marta Rosmery Hernandez Perez
A38: 35 | B38: Maria Marleni Marroquin Salazar | C38: CANOA | D38: LL | E38: 1 | F38: ARENERA | G38: RP | H38: 1 | I38: ARENERA | J38: RP | K38: 1 | L38: SAN EMILIANO | M38: RP | N38: 1 | O38: CANOA | P38: LL | Q38: 1 | R38: CANOA | S38: LL | T38: 1
A39: 36 | B39: Wilson Orlando Garcia Mendez
A40: 37 | B40: Suleyma Areli Guamush Marroquin | C40: CANOA | D40: LL | E40: 1 | F40: ARENERA | G40: RP | H40: 1 | I40: CAÑADA | J40: RP | K40: 1 | O40: SAN EMILIANO | P40: RP | Q40: 1
A41: 38 | B41: Jonathan Aguilar | C41: CANOA | D41: LL | E41: 1 | F41: CAÑADA | G41: RP | H41: 1 | I41: CAÑADA | J41: RP | K41: 1 | L41: CANOA | M41: LL | N41: 1 | R41: CANOA | S41: LL | T41: 1
...

Sheet DATA ORIGINAL
A1: FECHA | B1: No. ASIGNADO | C1: TRABAJADOR | D1: LOTE | E1: ACTIVIDAD | F1: UNIDADES | G1: NOMBRE ACTIVIDAD
A2: 46125 | B2: 1 | C2: Marco Antonio Solano | D2: CP | E2: CP | F2: 1 | G2: =VLOOKUP(E2,ACTIVIDADES!A1:D17,2) -> CAPORAL
A3: 46125 | B3: 2 | C3: Gildaberto Solano Arenas | D3: CP | E3: CP | F3: 1 | G3: =VLOOKUP(E3,ACTIVIDADES!A1:D17,2) -> CAPORAL
A4: 46125 | B4: 3 | C4: Henry Randolfo Hernandez Solano | D4: CASA | E4: BE | F4: 1 | G4: =VLOOKUP(E4,ACTIVIDADES!A2:D17,2) -> #N/A
A5: 46125 | B5: 4 | C5: Ruth Nohemi Alvarez Jimenez | D5: CASA | E5: MG | F5: 1 | G5: =VLOOKUP(E5,ACTIVIDADES!A3:D18,2) -> HACIENDA
A6: 46125 | B6: 5 | C6: Gaby Maidely Alvarez Jimenez | D6: MG | E6: MG | F6: 1 | G6: =VLOOKUP(E6,ACTIVIDADES!A4:D19,2) -> MANTENIMIENTO GENERAL
A7: 46125 | B7: 6 | C7: Enma Mannolia Perez Najera | D7: CANOA | E7: LL | F7: 1 | G7: =VLOOKUP(E7,ACTIVIDADES!A5:D20,2) -> LIMPIA LOTE
A8: 46125 | B8: 7 | C8: German Nolberto Solano Marroquin | D8: CANOA | E8: LL | F8: 1 | G8: =VLOOKUP(E8,ACTIVIDADES!A6:D21,2) -> DESCONOCIDA
A9: 46125 | B9: 8 | C9: Jaime Anibal Marroquin Salazar | D9: CANOA | E9: LL | F9: 1 | G9: =VLOOKUP(E9,ACTIVIDADES!A7:D22,2) -> HACIENDA
A10: 46125 | B10: 9 | C10: Adister Arcenio Marroquin | D10: SAN EMILIANO | E10: RP | F10: 1 | G10: =VLOOKUP(E10,ACTIVIDADES!A8:D23,2) -> DESCONOCIDA
A11: 46125 | B11: 10 | C11: Edgar Rolando Navas Chacon | G11: =VLOOKUP(E11,ACTIVIDADES!A9:D24,2) -> #N/A
A12: 46125 | B12: 11 | C12: Cindy Roxana Alvarez Lopez | G12: =VLOOKUP(E12,ACTIVIDADES!A11:D25,2) -> #N/A
A13: 46125 | B13: 12 | C13: Carmelo Marroquin Salazar | D13: CANOA | E13: LL | F13: 1 | G13: =VLOOKUP(E13,ACTIVIDADES!A14:D26,2) -> DESCONOCIDA
A14: 46125 | B14: 13 | C14: Erick Ronaldo Hernandez Martinez | G14: =VLOOKUP(E14,ACTIVIDADES!A17:D27,2) -> #N/A
A15: 46125 | B15: 14 | C15: Erica Yanira Alvarez Lopez | G15: =VLOOKUP(E15,ACTIVIDADES!A18:D28,2) -> #N/A
A16: 46125 | B16: 15 | C16: Elmer Alexander Hernandez Raliois | D16: BE | E16: BE | F16: 1 | G16: =VLOOKUP(E16,ACTIVIDADES!A18:D29,2) -> #N/A
A17: 46125 | B17: 16 | C17: Axel Amildo Alvarez Morales | D17: SAN EMILIANO | E17: RP | F17: 1 | G17: =VLOOKUP(E17,ACTIVIDADES!A18:D30,2) -> #N/A
A18: 46125 | B18: 17 | C18: Carlos Albino Garcia Mendez | G18: =VLOOKUP(E18,ACTIVIDADES!A19:D31,2) -> #N/A
A19: 46125 | B19: 18 | C19: Dixon Rene Hernandez Martinez | G19: =VLOOKUP(E19,ACTIVIDADES!A20:D32,2) -> #N/A
A20: 46125 | B20: 19 | C20: Jose alexander Navas Martinez | D20: CANOA | E20: LL | F20: 1 | G20: =VLOOKUP(E20,ACTIVIDADES!A21:D33,2) -> #N/A
A21: 46125 | B21: 20 | C21: Wilfrido Hernandez Ralios | G21: =VLOOKUP(E21,ACTIVIDADES!A22:D34,2) -> #N/A
A22: 46125 | B22: 21 | C22: Yaritza Amarilis Navas Sanchez | D22: CANOA | E22: LL | F22: 1 | G22: =VLOOKUP(E22,ACTIVIDADES!A23:D35,2) -> #N/A
A23: 46125 | B23: 22 | C23: Luz De Maria Martinez Solano | D23: CANOA | E23: LL | F23: 1 | G23: =VLOOKUP(E23,ACTIVIDADES!A24:D36,2) -> #N/A
A24: 46125 | B24: 23 | C24: Telma Elizabeth Hernandez Martinez | D24: CANOA | E24: LL | F24: 1 | G24: =VLOOKUP(E24,ACTIVIDADES!A25:D37,2) -> #N/A
A25: 46125 | B25: 24 | C25: Elderr Eduardo Hernandez Navas | D25: CANOA | E25: LL | F25: 1 | G25: =VLOOKUP(E25,ACTIVIDADES!A26:D38,2) -> #N/A
A26: 46125 | B26: 25 | C26: Francisco Alexander Navas Juarez | D26: CANOA | E26: LL | F26: 1 | G26: =VLOOKUP(E26,ACTIVIDADES!A27:D39,2) -> #N/A
A27: 46125 | B27: 26 | C27: Fernando Adelder Guamush Perez | D27: CANOA | E27: LL | F27: 1 | G27: =VLOOKUP(E27,ACTIVIDADES!A28:D40,2) -> #N/A
A28: 46125 | B28: 27 | C28: Jorge Luis Marroquin Salazar | D28: CANOA | E28: LL | F28: 1 | G28: =VLOOKUP(E28,ACTIVIDADES!A29:D41,2) -> #N/A
A29: 46125 | B29: 28 | C29: Baldomero Solano Marroquin | D29: CANOA | E29: LL | F29: 1 | G29: =VLOOKUP(E29,ACTIVIDADES!A30:D42,2) -> #N/A
A30: 46125 | B30: 29 | C30: Leidy Susana Solano Perez | D30: CANOA | E30: LL | F30: 1 | G30: =VLOOKUP(E30,ACTIVIDADES!A31:D43,2) -> #N/A
A31: 46125 | B31: 30 | C31: Jorge Odilio Solano Marroquin | D31: CANOA | E31: LL | F31: 1 | G31: =VLOOKUP(E31,ACTIVIDADES!A32:D44,2) -> #N/A
A32: 46125 | B32: 31 | C32: Maria Floridalma Alvarez Morales | D32: CANOA | E32: LL | F32: 1 | G32: =VLOOKUP(E32,ACTIVIDADES!A33:D45,2) -> #N/A
A33: 46125 | B33: 32 | C33: Oliver Gerardo Aguilar Sanchez | D33: CANOA | E33: LL | F33: 1 | G33: =VLOOKUP(E33,ACTIVIDADES!A34:D46,2) -> #N/A
A34: 46125 | B34: 33 | C34: Julia Yanira Marroquin | D34: CANOA | E34: LL | F34: 1 | G34: =VLOOKUP(E34,ACTIVIDADES!A35:D47,2) -> #N/A
A35: 46125 | B35: 34 | C35: Marta Rosmery Hernandez Perez | G35: =VLOOKUP(E35,ACTIVIDADES!A36:D48,2) -> #N/A
A36: 46125 | B36: 35 | C36: Maria Marleni Marroquin Salazar | D36: CANOA | E36: LL | F36: 1 | G36: =VLOOKUP(E36,ACTIVIDADES!A37:D49,2) -> #N/A
A37: 46125 | B37: 36 | C37: Wilson Orlando Garcia Mendez | G37: =VLOOKUP(E37,ACTIVIDADES!A38:D50,2) -> #N/A
A38: 46125 | B38: 37 | C38: Suleyma Areli Guamush Marroquin | D38: CANOA | E38: LL | F38: 1 | G38: =VLOOKUP(E38,ACTIVIDADES!A39:D51,2) -> #N/A
A39: 46125 | B39: 38 | C39: Jonathan Aguilar | D39: CANOA | E39: LL | F39: 1 | G39: =VLOOKUP(E39,ACTIVIDADES!A40:D52,2) -> #N/A
A40: 46125 | B40: 39 | C40: Artemio Danilo Solano Marroquin | D40: CANOA | E40: LL | F40: 1 | G40: =VLOOKUP(E40,ACTIVIDADES!A41:D53,2) -> #N/A
...

Sheet ACTIVIDADES
A1: BE | B1: BENEFICIO | C1: DÍA | D1: 75
A2: BN | B2: BENEFICIO | C2: DÍA | D2: 75
A3: CA | B3: CARBON | C3: DÍA | D3: 75
A4: CP | B4: CAPORAL | C4: DÍA | D4: 100
A5: FE | B5: FERTILIZACION | C5: DÍA | D5: 17.5
A6: FERIADO | B6: FERIADO | C6: DÍA | D6: 75
A7: FG | B7: APLICACION DE FUNGICIDA | C7: DÍA | D7: 75
A8: LL | B8: LIMPIA LOTE | C8: DÍA | D8: 75
A9: MG | B9: MANTENIMIENTO GENERAL | C9: DÍA | D9: 75
A10: HA | B10: HACIENDA | C10: DIA | D10: 65
A11: MS | B11: MANEJO DE SOMBRA | C11: DÍA | D11: 75
A12: SP | B12: SEPTIMO | C12: DIA | D12: 75
... A17: TZ | B17: TRAZADO PARA SIEMBRA | C17: DÍA | D17: 75

Sheet PLANILLA
A1: FECHA | B1: No. ASIGNADO | C1: TRABAJADOR | D1: LOTE | E1: ACTIVIDAD | F1: NOMBRE ACTIVIDAD | G1: CANTIDAD DE UNIDADES | H1: COSTOPOR UNIDAD | I1: COSTO TOTAL
A2: 46156 | B2: 1 | C2: Marco Antonio Solano | D2: CP | E2: CP | F2: =IFERROR(VLOOKUP(TRIM(E2),ACTIVIDADES!$A$1:$D$17,2,FALSE),"NO ENCONTRADO") -> CAPORAL | G2: 1 | H2: =IFERROR(VLOOKUP(TRIM(E2),ACTIVIDADES!$A$1:$D$17,4,FALSE),"") -> 100 | I2: =IFERROR(G2*H2,"") -> 100
A3: 46156 | B3: 2 | C3: Gildaberto Solano Arenas | D3: CP | E3: CP | F3: =IFERROR(VLOOKUP(TRIM(E3),ACTIVIDADES!$A$1:$D$17,2,FALSE),"NO ENCONTRADO") -> CAPORAL | G3: 1 | H3: =IFERROR(VLOOKUP(TRIM(E3),ACTIVIDADES!$A$1:$D$17,4,FALSE),"") -> 100 | I3: =IFERROR(G3*H3,"") -> 100
A4: 46156 | B4: 3 | C4: Henry Randolfo Hernandez Solano | D4: CP | E4: CP | F4: =IFERROR(VLOOKUP(TRIM(E4),ACTIVIDADES!$A$1:$D$17,2,FALSE),"NO ENCONTRADO") -> CAPORAL | G4: 1 | H4: =IFERROR(VLOOKUP(TRIM(E4),ACTIVIDADES!$A$1:$D$17,4,FALSE),"") -> 100 | I4: =IFERROR(G4*H4,"") -> 100
A5: 46156 | B5: 4 | C5: Ruth Nohemi Alvarez Jimenez | D5: HACIENDA | E5: HA | F5: =IFERROR(VLOOKUP(TRIM(E5),ACTIVIDADES!$A$1:$D$17,2,FALSE),"NO ENCONTRADO") -> HACIENDA | G5: 1 | H5: =IFERROR(VLOOKUP(TRIM(E5),ACTIVIDADES!$A$1:$D$17,4,FALSE),"") -> 65 | I5: =IFERROR(G5*H5,"") -> 65
A6: 46156 | B6: 5 | C6: Gaby Maidely Alvarez Jimenez | D6: HACIENDA | E6: HA | F6: =IFERROR(VLOOKUP(TRIM(E6),ACTIVIDADES!$A$1:$D$17,2,FALSE),"NO ENCONTRADO") -> HACIENDA | G6: 1 | H6: =IFERROR(VLOOKUP(TRIM(E6),ACTIVIDADES!$A$1:$D$17,4,FALSE),"") -> 65 | I6: =IFERROR(G6*H6,"") -> 65
A7: 46156 | B7: 6 | C7: Enma Mannolia Perez Najera | D7: CORONA | E7: MS | F7: =IFERROR(VLOOKUP(TRIM(E7),ACTIVIDADES!$A$1:$D$17,2,FALSE),"NO ENCONTRADO") -> MANEJO DE SOMBRA | G7: 1 | H7: =IFERROR(VLOOKUP(TRIM(E7),ACTIVIDADES!$A$1:$D$17,4,FALSE),"") -> 75 | I7: =IFERROR(G7*H7,"") -> 75
A8: 46156 | B8: 7 | C8: German Nolberto Solano Marroquin | D8: CANOA | E8: TZ | F8: =IFERROR(VLOOKUP(TRIM(E8),ACTIVIDADES!$A$1:$D$17,2,FALSE),"NO ENCONTRADO") -> TRAZADO PARA SIEMBRA | G8: 1 | H8: =IFERROR(VLOOKUP(TRIM(E8),ACTIVIDADES!$A$1:$D$17,4,FALSE),"") -> 75 | I8: =IFERROR(G8*H8,"") -> 75
A9: 46156 | B9: 8 | C9: Jaime Anibal Marroquin Salazar | D9: CORONA | E9: MS | F9: =IFERROR(VLOOKUP(TRIM(E9),ACTIVIDADES!$A$1:$D$17,2,FALSE),"NO ENCONTRADO") -> MANEJO DE SOMBRA | G9: 1 | H9: =IFERROR(VLOOKUP(TRIM(E9),ACTIVIDADES!$A$1:$D$17,4,FALSE),"") -> 75 | I9: =IFERROR(G9*H9,"") -> 75
A10: 46156 | B10: 9 | C10: Adister Arcenio Marroquin | D10: CORONA | E10: MS | F10: =IFERROR(VLOOKUP(TRIM(E10),ACTIVIDADES!$A$1:$D$17,2,FALSE),"NO ENCONTRADO") -> MANEJO DE SOMBRA | G10: 1 | H10: =IFERROR(VLOOKUP(TRIM(E10),ACTIVIDADES!$A$1:$D$17,4,FALSE),"") -> 75 | I10: =IFERROR(G10*H10,"") -> 75
A11: 46156 | B11: 12 | C11: Carmelo Marroquin Salazar | D11: CORONA | E11: MS | F11: =IFERROR(VLOOKUP(TRIM(E11),ACTIVIDADES!$A$1:$D$17,2,FALSE),"NO ENCONTRADO") -> MANEJO DE SOMBRA | G11: 1 | H11: =IFERROR(VLOOKUP(TRIM(E11),ACTIVIDADES!$A$1:$D$17,4,FALSE),"") -> 75 | I11: =IFERROR(G11*H11,"") -> 75
A12: 46156 | B12: 15 | C12: Elmer Alexander Hernandez Raliois | D12: CRUZ 1 | E12: MG | F12: =IFERROR(VLOOKUP(TRIM(E12),ACTIVIDADES!$A$1:$D$17,2,FALSE),"NO ENCONTRADO") -> MANTENIMIENTO GENERAL | G12: 1 | H12: =IFERROR(VLOOKUP(TRIM(E12),ACTIVIDADES!$A$1:$D$17,4,FALSE),"") -> 75 | I12: =IFERROR(G12*H12,"") -> 75
A13: 46156 | B13: 16 | C13: Axel Amildo Alvarez Morales | D13: CORONA | E13: MS | F13: =IFERROR(VLOOKUP(TRIM(E13),ACTIVIDADES!$A$1:$D$17,2,FALSE),"NO ENCONTRADO") -> MANEJO DE SOMBRA | G13: 1 | H13: =IFERROR(VLOOKUP(TRIM(E13),ACTIVIDADES!$A$1:$D$17,4,FALSE),"") -> 75 | I13: =IFERROR(G13*H13,"") -> 75
... A652: 46176 | B652: 40 | C652: Iris Maricela Hernandez Martinez | D652: CRUZ 2 | E652: LL | F652: =IFERROR(VLOOKUP(TRIM(E652),ACTIVIDADES!$A$1:$D$17,2,FALSE),"NO ENCONTRADO") -> LIMPIA LOTE | G652: 0.5 | H652: =IFERROR(VLOOKUP(TRIM(E652),ACTIVIDADES!$A$1:$D$17,4,FALSE),"") -> 75 | I652: =IFERROR(G652*H652,"") -> 37.5
I653: =SUM(I2:I652) -> 44661.55

Sheet PAGOS
A1: TRABAJADOR | B1: TOTAL | C1: SEPTIMOS | D1: DESCUENTOS | E1: TOTAL A PAGAR | F1: BANCO | G1: NUMERO DE CUENTA BANCARIA
A2: Adister Arcenio Marroquin | B2: =SUMIF(PLANILLA!$C$2:$C$999,PAGOS!A2,PLANILLA!$I$2:$I$999) -> 1163 | C2: =75*2 -> 150 | D2: 40 | E2: =+B2+C2-D2 -> 1273
A3: Artemio Danilo Solano Marroquin | B3: =SUMIF(PLANILLA!$C$2:$C$999,PAGOS!A3,PLANILLA!$I$2:$I$999) -> 1276.5 | C3: =75*2 -> 150 | D3: 0 | E3: =+B3+C3-D3 -> 1426.5
A4: Axel Amildo Alvarez Morales | B4: =SUMIF(PLANILLA!$C$2:$C$999,PAGOS!A4,PLANILLA!$I$2:$I$999) -> 1148 | C4: =75*1 -> 75 | D4: 40 | E4: =+B4+C4-D4 -> 1183 | F4: BANRURAL | G4: 4029152135
A5: Baldomero Solano Marroquin | B5: =SUMIF(PLANILLA!$C$2:$C$999,PAGOS!A5,PLANILLA!$I$2:$I$999) -> 1205 | C5: =75*2 -> 150 | D5: 0 | E5: =+B5+C5-D5 -> 1355 | F5: BANRURAL | G5: 4029163700
A6: Carlos Albino Garcia Mendez | B6: =SUMIF(PLANILLA!$C$2:$C$999,PAGOS!A6,PLANILLA!$I$2:$I$999) -> 1182.5 | C6: =75*2 -> 150 | D6: 40 | E6: =+B6+C6-D6 -> 1292.5
A7: Carmelo Marroquin Salazar | B7: =SUMIF(PLANILLA!$C$2:$C$999,PAGOS!A7,PLANILLA!$I$2:$I$999) -> 1049 | C7: =75*1 -> 75 | D7: 40 | E7: =+B7+C7-D7 -> 1084
A8: Cindy Roxana Alvarez Lopez | B8: =SUMIF(PLANILLA!$C$2:$C$999,PAGOS!A8,PLANILLA!$I$2:$I$999) -> 1041.5 | C8: =75*2 -> 150 | D8: 0 | E8: =+B8+C8-D8 -> 1191.5 | F8: BANRURAL | G8: 4029166385
A9: Dixon Rene Hernandez Martinez | B9: =SUMIF(PLANILLA!$C$2:$C$999,PAGOS!A9,PLANILLA!$I$2:$I$999) -> 1022.5 | C9: =75*2 -> 150 | D9: 40 | E9: =+B9+C9-D9 -> 1132.5 | F9: BANRURAL | G9: 4029157433
A10: Edgar Rolando Navas Chacon | B10: =SUMIF(PLANILLA!$C$2:$C$999,PAGOS!A10,PLANILLA!$I$2:$I$999) -> 871.5 | C10: =75*1 -> 75 | D10: 0 | E10: =+B10+C10-D10 -> 946.5 | F10: BANRURAL | G10: 4029152117
A11: Elderr Eduardo Hernandez Navas | B11: =SUMIF(PLANILLA!$C$2:$C$999,PAGOS!A11,PLANILLA!$I$2:$I$999) -> 1157 | C11: =75*2 -> 150 | D11: 0 | E11: =+B11+C11-D11 -> 1307 | F11: BANRURAL | G11: 3029028657
A12: Elmer Alexander Hernandez Raliois | B12: =SUMIF(PLANILLA!$C$2:$C$999,PAGOS!A12,PLANILLA!$I$2:$I$999) -> 1203 | C12: =75*2 -> 150 | D12: 0 | E12: =+B12+C12-D12 -> 1353
A13: Enma Mannolia Perez Najera | B13: =SUMIF(PLANILLA!$C$2:$C$999,PAGOS!A13,PLANILLA!$I$2:$I$999) -> 1228.25 | C13: =75*2 -> 150 | D13: 0 | E13: =+B13+C13-D13 -> 1378.25
A14: Erica Yanira Alvarez Lopez | B14: =SUMIF(PLANILLA!$C$2:$C$999,PAGOS!A14,PLANILLA!$I$2:$I$999) -> 966.5 | C14: =75*2 -> 150 | D14: 0 | E14: =+B14+C14-D14 -> 1116.5 | F14: BANRURAL | G14: 4029166371
A15: Erick Ronaldo Hernandez Martinez | B15: =SUMIF(PLANILLA!$C$2:$C$999,PAGOS!A15,PLANILLA!$I$2:$I$999) -> 978 | C15: =75*2 -> 150 | D15: 0 | E15: =+B15+C15-D15 -> 1128 | F15: BANRURAL | G15: 4029166399
A16: Fernando Adelder Guamush Perez | B16: =SUMIF(PLANILLA!$C$2:$C$999,PAGOS!A16,PLANILLA!$I$2:$I$999) -> 1152.5 | C16: =75*1 -> 75 | D16: 0 | E16: =+B16+C16-D16 -> 1227.5
A17: Francisco Alexander Navas Juarez | B17: =SUMIF(PLANILLA!$C$2:$C$999,PAGOS!A17,PLANILLA!$I$2:$I$999) -> 641.5 | C17: =75*0 -> 0 | D17: 0 | E17: =+B17+C17-D17 -> 641.5 | F17: BANRURAL | G17: 3029028689
A18: Gaby Maidely Alvarez Jimenez | B18: =SUMIF(PLANILLA!$C$2:$C$999,PAGOS!A18,PLANILLA!$I$2:$I$999) -> 1171.5 | C18: =75*2 -> 150 | D18: 0 | E18: =+B18+C18-D18 -> 1321.5 | F18: BANRURAL | G18: 4029165827
A19: German Nolberto Solano Marroquin | B19: =SUMIF(PLANILLA!$C$2:$C$999,PAGOS!A19,PLANILLA!$I$2:$I$999) -> 1276.5 | C19: =75*2 -> 150 | D19: 40 | E19: =+B19+C19-D19 -> 1386.5
A20: Gildaberto Solano Arenas | B20: =SUMIF(PLANILLA!$C$2:$C$999,PAGOS!A20,PLANILLA!$I$2:$I$999) -> 1701.5 | C20: =75*2 -> 150 | D20: 0 | E20: =+B20+C20-D20 -> 1851.5
A21: Henry Randolfo Hernandez Solano | B21: =SUMIF(PLANILLA!$C$2:$C$999,PAGOS!A21,PLANILLA!$I$2:$I$999) -> 1676.5 | C21: =75*2 -> 150 | D21: 0 | E21: =+B21+C21-D21 -> 1826.5
A22: Jaime Anibal Marroquin Salazar | B22: =SUMIF(PLANILLA!$C$2:$C$999,PAGOS!A22,PLANILLA!$I$2:$I$999) -> 1198.5 | C22: =75*2 -> 150 | D22: 40 | E22: =+B22+C22-D22 -> 1308.5
A23: Jonathan Aguilar | B23: =SUMIF(PLANILLA!$C$2:$C$999,PAGOS!A23,PLANILLA!$I$2:$I$999) -> 994 | C23: =75*1 -> 75 | D23: 0 | E23: =+B23+C23-D23 -> 1069 | F23: BANRURAL | G23: 4029161954
A24: Jorge Luis Marroquin Salazar | B24: =SUMIF(PLANILLA!$C$2:$C$999,PAGOS!A24,PLANILLA!$I$2:$I$999) -> 453 | C24: =75*0 -> 0 | D24: 40 | E24: =+B24+C24-D24 -> 413 | F24: BANRURAL | G24: 4029159358
A25: Jorge Odilio Solano Marroquin | B25: =SUMIF(PLANILLA!$C$2:$C$999,PAGOS!A25,PLANILLA!$I$2:$I$999) -> 1202.25 | C25: =75*2 -> 150 | D25: 40 | E25: =+B25+C25-D25 -> 1312.25
A26: Jose Alexander Navas Martinez | B26: =SUMIF(PLANILLA!$C$2:$C$999,PAGOS!A26,PLANILLA!$I$2:$I$999) -> 901.5 | C26: =75*1 -> 75 | D26: 0 | E26: =+B26+C26-D26 -> 976.5 | F26: BANRURAL | G26: 4029152167
A27: Julia Yanira Marroquin | B27: =SUMIF(PLANILLA!$C$2:$C$999,PAGOS!A27,PLANILLA!$I$2:$I$999) -> 1064 | C27: =75*1 -> 75 | D27: 0 | E27: =+B27+C27-D27 -> 1139 | F27: BANRURAL | G27: 4029152153
A28: Leidy Susana Solano Perez | B28: =SUMIF(PLANILLA!$C$2:$C$999,PAGOS!A28,PLANILLA!$I$2:$I$999) -> 1191.5 | C28: =75*2 -> 150 | D28: 0 | E28: =+B28+C28-D28 -> 1341.5
A29: Luz De Maria Martinez Solano | B29: =SUMIF(PLANILLA!$C$2:$C$999,PAGOS!A29,PLANILLA!$I$2:$I$999) -> 1139 | C29: =75*2 -> 150 | D29: 0 | E29: =+B29+C29-D29 -> 1289
A30: Marco Antonio Solano | B30: =SUMIF(PLANILLA!$C$2:$C$999,PAGOS!A30,PLANILLA!$I$2:$I$999) -> 1801.5 | C30: =75*2 -> 150 | D30: 0 | E30: =+B30+C30-D30 -> 1951.5 | F30: BANRURAL | G30: 4029152218
A31: Maria Floridalma Alvarez Morales | B31: =SUMIF(PLANILLA!$C$2:$C$999,PAGOS!A31,PLANILLA!$I$2:$I$999) -> 1190.75 | C31: =75*2 -> 150 | D31: 0 | E31: =+B31+C31-D31 -> 1340.75 | F31: BANRURAL | G31: 4029151948
A32: Maria Marleni Marroquin Salazar | B32: =SUMIF(PLANILLA!$C$2:$C$999,PAGOS!A32,PLANILLA!$I$2:$I$999) -> 1116.5 | C32: =75*2 -> 150 | D32: 0 | E32: =+B32+C32-D32 -> 1266.5 | F32: BANRURAL | G32: 4029161922
A33: Marta Rosmery Hernandez Perez | B33: =SUMIF(PLANILLA!$C$2:$C$999,PAGOS!A33,PLANILLA!$I$2:$I$999) -> 1046.2 | C33: =75*1 -> 75 | D33: 0 | E33: =+B33+C33-D33 -> 1121.2 | F33: BANRURAL | G33: 4029159110
A34: Oliver Gerardo Aguilar Sanchez | B34: =SUMIF(PLANILLA!$C$2:$C$999,PAGOS!A34,PLANILLA!$I$2:$I$999) -> 1002.5 | C34: =75*0 -> 0 | D34: 40 | E34: =+B34+C34-D34 -> 962.5 | F34: BANRURAL | G34: 4029157516
A35: Ruth Nohemi Alvarez Jimenez | B35: =SUMIF(PLANILLA!$C$2:$C$999,PAGOS!A35,PLANILLA!$I$2:$I$999) -> 1171.5 | C35: =75*2 -> 150 | D35: 0 | E35: =+B35+C35-D35 -> 1321.5 | F35: BANRURAL | G35: 4029165845
A36: Suleyma Areli Guamush Marroquin | B36: =SUMIF(PLANILLA!$C$2:$C$999,PAGOS!A36,PLANILLA!$I$2:$I$999) -> 1153.25 | C36: =75*1 -> 75 | D36: 0 | E36: =+B36+C36-D36 -> 1228.25 | F36: BANRURAL | G36: 3029026017
A37: Telma Elizabeth Hernandez Martinez | B37: =SUMIF(PLANILLA!$C$2:$C$999,PAGOS!A37,PLANILLA!$I$2:$I$999) -> 1116.5 | C37: =75*1 -> 75 | D37: 0 | E37: =+B37+C37-D37 -> 1191.5 | F37: BANRURAL | G37: 4396067306
A38: Wilfrido Hernandez Ralios | B38: =SUMIF(PLANILLA!$C$2:$C$999,PAGOS!A38,PLANILLA!$I$2:$I$999) -> 1128 | C38: =75*2 -> 150 | D38: 0 | E38: =+B38+C38-D38 -> 1278 | F38: BANRURAL | G38: 4015403844
A39: Wilson Orlando Garcia Mendez | B39: =SUMIF(PLANILLA!$C$2:$C$999,PAGOS!A39,PLANILLA!$I$2:$I$999) -> 1008.5 | C39: =75*2 -> 150 | D39: 40 | E39: =+B39+C39-D39 -> 1118.5 | F39: BANRURAL | G39: 3029029349
A40: Yaritza Amarilis Navas Sanchez | B40: =SUMIF(PLANILLA!$C$2:$C$999,PAGOS!A40,PLANILLA!$I$2:$I$999) -> 1116.5 | C40: =75*2 -> 150 | D40: 0 | E40: =+B40+C40-D40 -> 1266.5 | F40: BANRURAL | G40: 4029165592
...
